{
 "cells": [
  {
   "cell_type": "code",
   "execution_count": 2,
   "id": "e7919977-e3c3-4002-b90a-21f0f688e263",
   "metadata": {},
   "outputs": [],
   "source": [
    "%load_ext autoreload\n",
    "%autoreload 2"
   ]
  },
  {
   "cell_type": "code",
   "execution_count": 3,
   "id": "c5a2ef80-d0a8-4e27-9306-f8d5309e0b4b",
   "metadata": {},
   "outputs": [],
   "source": [
    "import os\n",
    "os.environ[\"CUDA_DEVICE_ORDER\"]=\"PCI_BUS_ID\"   # see issue #152\n",
    "os.environ[\"CUDA_VISIBLE_DEVICES\"]=\"5\""
   ]
  },
  {
   "cell_type": "code",
   "execution_count": 10,
   "id": "80bee5bd-c3dd-4c1c-a7f2-086b160f95a2",
   "metadata": {},
   "outputs": [],
   "source": [
    "import glob\n",
    "import tensorflow as tf\n",
    "import cv2\n",
    "import numpy as np\n",
    "from tqdm.auto import tqdm\n",
    "from skimage import transform\n",
    "from ganime.visualization.videos import display_videos\n",
    "from joblib import Parallel, delayed"
   ]
  },
  {
   "cell_type": "code",
   "execution_count": 5,
   "id": "ea0b2ad1-d2ca-4d1f-ae99-fe2413c17fa9",
   "metadata": {},
   "outputs": [],
   "source": [
    "source_folder = \"../../../data/kny/scenes/*/*.mp4\""
   ]
  },
  {
   "cell_type": "code",
   "execution_count": 6,
   "id": "4c6f7499-11cb-4d63-8724-35e205d6df74",
   "metadata": {},
   "outputs": [],
   "source": [
    "video_paths = sorted(glob.glob(source_folder))"
   ]
  },
  {
   "cell_type": "code",
   "execution_count": 7,
   "id": "b8fd1890-39e0-4a30-a4c9-993776b53e54",
   "metadata": {},
   "outputs": [],
   "source": [
    "def resize_video(video, new_height=64, new_width=128):\n",
    "    n_frames = int(video.get(cv2.CAP_PROP_FRAME_COUNT))\n",
    "    frames = np.zeros((n_frames, new_height, new_width, 3))\n",
    "    i = 0\n",
    "    while True:\n",
    "        ret, frame = video.read()\n",
    "        if ret == True:\n",
    "            resized = cv2.resize(frame,(new_width, new_height),fx=0,fy=0, interpolation = cv2.INTER_CUBIC)\n",
    "            frames[i] = resized\n",
    "        else:\n",
    "            break\n",
    "        i += 1\n",
    "    return frames"
   ]
  },
  {
   "cell_type": "code",
   "execution_count": 8,
   "id": "640ee2f0-7082-4219-a04e-a8da9676709d",
   "metadata": {},
   "outputs": [],
   "source": [
    "def frame_count(video_path, manual=False):\n",
    "    def manual_count(handler):\n",
    "        frames = 0\n",
    "        while True:\n",
    "            status, frame = handler.read()\n",
    "            if not status:\n",
    "                break\n",
    "            frames += 1\n",
    "        return frames \n",
    "\n",
    "    cap = cv2.VideoCapture(video_path)\n",
    "    # Slow, inefficient but 100% accurate method \n",
    "    if manual:\n",
    "        frames = manual_count(cap)\n",
    "    # Fast, efficient but inaccurate method\n",
    "    else:\n",
    "        try:\n",
    "            frames = int(cap.get(cv2.CAP_PROP_FRAME_COUNT))\n",
    "        except:\n",
    "            frames = manual_count(cap)\n",
    "    cap.release()\n",
    "    return frames"
   ]
  },
  {
   "cell_type": "code",
   "execution_count": 11,
   "id": "fdd947d3-1933-4960-a711-90d8f10e5ec9",
   "metadata": {},
   "outputs": [
    {
     "data": {
      "application/vnd.jupyter.widget-view+json": {
       "model_id": "d58b779eb38745eea4f957b34de2d6b0",
       "version_major": 2,
       "version_minor": 0
      },
      "text/plain": [
       "  0%|          | 0/17338 [00:00<?, ?it/s]"
      ]
     },
     "metadata": {},
     "output_type": "display_data"
    }
   ],
   "source": [
    "all_frame_numbers = Parallel(n_jobs=-1)(delayed(frame_count)(path) for path in tqdm(video_paths))\n",
    "all_frame_numbers = np.array(all_frame_numbers)"
   ]
  },
  {
   "cell_type": "code",
   "execution_count": 12,
   "id": "8fd7a4fe-bd06-4144-a2ab-58937b5c4577",
   "metadata": {},
   "outputs": [],
   "source": [
    "def get_value_to_split(array):\n",
    "    n_elements = array.shape[0]\n",
    "    range_min = 15\n",
    "    range_max = 25\n",
    "    \n",
    "    lowest_remainder = range_max\n",
    "    lowest_id = range_max\n",
    "    for i in range(range_min, range_max):\n",
    "        remainder = n_elements % i\n",
    "        if remainder <= lowest_remainder:\n",
    "            lowest_id = i\n",
    "            lowest_remainder = remainder\n",
    "    return lowest_id"
   ]
  },
  {
   "cell_type": "code",
   "execution_count": 13,
   "id": "6a19a569-df9e-46b1-8cfa-f9218e06bc0e",
   "metadata": {},
   "outputs": [],
   "source": [
    "def cut_array(array, number):\n",
    "    for i in range(array.shape[0] // number):\n",
    "        start = i * number\n",
    "        end = (i+1) * number\n",
    "        if array.shape[0] - end < number:\n",
    "            end = array.shape[0]\n",
    "            yield start, end, len(array[start:end])\n",
    "        else:\n",
    "            yield start, end, len(array[start:end])"
   ]
  },
  {
   "cell_type": "code",
   "execution_count": 27,
   "id": "34c4ed86-365e-453c-bca6-f23a8487b091",
   "metadata": {},
   "outputs": [
    {
     "name": "stdout",
     "output_type": "stream",
     "text": [
      "(0, 16, 16)\n",
      "(16, 33, 17)\n"
     ]
    }
   ],
   "source": [
    "array = np.arange(33)\n",
    "for i in cut_array(array, get_value_to_split(array)):\n",
    "    print(i)"
   ]
  },
  {
   "cell_type": "code",
   "execution_count": 105,
   "id": "53bf0f53-4eab-4f8f-a914-1d2a7b573bdf",
   "metadata": {},
   "outputs": [
    {
     "data": {
      "text/plain": [
       "20"
      ]
     },
     "execution_count": 105,
     "metadata": {},
     "output_type": "execute_result"
    }
   ],
   "source": [
    "get_value_to_split(array)"
   ]
  },
  {
   "cell_type": "code",
   "execution_count": 29,
   "id": "2c33165a-e85f-4b60-828a-6a7ac41c4aa2",
   "metadata": {},
   "outputs": [
    {
     "data": {
      "text/plain": [
       "54.0"
      ]
     },
     "execution_count": 29,
     "metadata": {},
     "output_type": "execute_result"
    }
   ],
   "source": [
    "np.median(all_frame_numbers)"
   ]
  },
  {
   "cell_type": "code",
   "execution_count": 7,
   "id": "d4de5578-8283-491f-b024-21449d3c3598",
   "metadata": {},
   "outputs": [],
   "source": [
    "def load_video(path):\n",
    "    video = cv2.VideoCapture(path)\n",
    "    video = resize_video(video)\n",
    "    #video = tf.convert_to_tensor(video)\n",
    "    return video\n",
    "    "
   ]
  },
  {
   "cell_type": "code",
   "execution_count": 8,
   "id": "c412b34d-be81-4505-9520-44cb6c51b8e9",
   "metadata": {},
   "outputs": [
    {
     "data": {
      "application/vnd.jupyter.widget-view+json": {
       "model_id": "96c0eb32853849d69d6995261fadc103",
       "version_major": 2,
       "version_minor": 0
      },
      "text/plain": [
       "  0%|          | 0/17338 [00:00<?, ?it/s]"
      ]
     },
     "metadata": {},
     "output_type": "display_data"
    },
    {
     "name": "stderr",
     "output_type": "stream",
     "text": [
      "/usr/local/lib/python3.8/dist-packages/joblib/externals/loky/process_executor.py:703: UserWarning: A worker stopped while some jobs were given to the executor. This can be caused by a too short worker timeout or by a memory leak.\n",
      "  warnings.warn(\n",
      "Process LokyProcess-24:\n",
      "Traceback (most recent call last):\n",
      "  File \"/usr/lib/python3.8/multiprocessing/process.py\", line 315, in _bootstrap\n",
      "    self.run()\n",
      "  File \"/usr/lib/python3.8/multiprocessing/process.py\", line 108, in run\n",
      "    self._target(*self._args, **self._kwargs)\n",
      "  File \"/usr/local/lib/python3.8/dist-packages/joblib/externals/loky/process_executor.py\", line 455, in _process_worker\n",
      "    result_queue.put(pid)\n",
      "  File \"/usr/local/lib/python3.8/dist-packages/joblib/externals/loky/backend/queues.py\", line 239, in put\n",
      "    with self._wlock:\n",
      "  File \"/usr/local/lib/python3.8/dist-packages/joblib/externals/loky/backend/synchronize.py\", line 104, in __enter__\n",
      "    return self._semlock.acquire()\n",
      "KeyboardInterrupt\n",
      "Process LokyProcess-99:\n",
      "Traceback (most recent call last):\n",
      "  File \"/usr/lib/python3.8/multiprocessing/process.py\", line 315, in _bootstrap\n",
      "    self.run()\n",
      "  File \"/usr/lib/python3.8/multiprocessing/process.py\", line 108, in run\n",
      "    self._target(*self._args, **self._kwargs)\n",
      "  File \"/usr/local/lib/python3.8/dist-packages/joblib/externals/loky/process_executor.py\", line 455, in _process_worker\n",
      "    result_queue.put(pid)\n",
      "  File \"/usr/local/lib/python3.8/dist-packages/joblib/externals/loky/backend/queues.py\", line 239, in put\n",
      "    with self._wlock:\n",
      "  File \"/usr/local/lib/python3.8/dist-packages/joblib/externals/loky/backend/synchronize.py\", line 104, in __enter__\n",
      "    return self._semlock.acquire()\n",
      "KeyboardInterrupt\n",
      "Process LokyProcess-94:\n",
      "Traceback (most recent call last):\n",
      "  File \"/usr/lib/python3.8/multiprocessing/process.py\", line 315, in _bootstrap\n",
      "    self.run()\n",
      "  File \"/usr/lib/python3.8/multiprocessing/process.py\", line 108, in run\n",
      "    self._target(*self._args, **self._kwargs)\n",
      "  File \"/usr/local/lib/python3.8/dist-packages/joblib/externals/loky/process_executor.py\", line 455, in _process_worker\n",
      "    result_queue.put(pid)\n",
      "  File \"/usr/local/lib/python3.8/dist-packages/joblib/externals/loky/backend/queues.py\", line 239, in put\n",
      "    with self._wlock:\n",
      "  File \"/usr/local/lib/python3.8/dist-packages/joblib/externals/loky/backend/synchronize.py\", line 104, in __enter__\n",
      "    return self._semlock.acquire()\n",
      "KeyboardInterrupt\n",
      "Process LokyProcess-87:\n",
      "Traceback (most recent call last):\n",
      "  File \"/usr/lib/python3.8/multiprocessing/process.py\", line 315, in _bootstrap\n",
      "    self.run()\n",
      "  File \"/usr/lib/python3.8/multiprocessing/process.py\", line 108, in run\n",
      "    self._target(*self._args, **self._kwargs)\n",
      "  File \"/usr/local/lib/python3.8/dist-packages/joblib/externals/loky/process_executor.py\", line 455, in _process_worker\n",
      "    result_queue.put(pid)\n",
      "  File \"/usr/local/lib/python3.8/dist-packages/joblib/externals/loky/backend/queues.py\", line 239, in put\n",
      "    with self._wlock:\n",
      "  File \"/usr/local/lib/python3.8/dist-packages/joblib/externals/loky/backend/synchronize.py\", line 104, in __enter__\n",
      "    return self._semlock.acquire()\n",
      "KeyboardInterrupt\n",
      "Process LokyProcess-108:\n",
      "Traceback (most recent call last):\n",
      "  File \"/usr/local/lib/python3.8/dist-packages/joblib/externals/loky/process_executor.py\", line 343, in _sendback_result\n",
      "    result_queue.put(_ResultItem(work_id, result=result,\n",
      "  File \"/usr/local/lib/python3.8/dist-packages/joblib/externals/loky/backend/queues.py\", line 239, in put\n",
      "    with self._wlock:\n",
      "  File \"/usr/local/lib/python3.8/dist-packages/joblib/externals/loky/backend/synchronize.py\", line 104, in __enter__\n",
      "    return self._semlock.acquire()\n",
      "KeyboardInterrupt\n",
      "\n",
      "During handling of the above exception, another exception occurred:\n",
      "\n",
      "Traceback (most recent call last):\n",
      "  File \"/usr/lib/python3.8/multiprocessing/process.py\", line 315, in _bootstrap\n",
      "    self.run()\n",
      "  File \"/usr/lib/python3.8/multiprocessing/process.py\", line 108, in run\n",
      "    self._target(*self._args, **self._kwargs)\n",
      "  File \"/usr/local/lib/python3.8/dist-packages/joblib/externals/loky/process_executor.py\", line 423, in _process_worker\n",
      "    _sendback_result(result_queue, call_item.work_id, result=r)\n",
      "  File \"/usr/local/lib/python3.8/dist-packages/joblib/externals/loky/process_executor.py\", line 347, in _sendback_result\n",
      "    result_queue.put(_ResultItem(work_id, exception=exc))\n",
      "  File \"/usr/local/lib/python3.8/dist-packages/joblib/externals/loky/backend/queues.py\", line 239, in put\n",
      "    with self._wlock:\n",
      "  File \"/usr/local/lib/python3.8/dist-packages/joblib/externals/loky/backend/synchronize.py\", line 104, in __enter__\n",
      "    return self._semlock.acquire()\n",
      "KeyboardInterrupt\n",
      "Process LokyProcess-102:\n",
      "Traceback (most recent call last):\n",
      "  File \"/usr/local/lib/python3.8/dist-packages/joblib/externals/loky/process_executor.py\", line 343, in _sendback_result\n",
      "    result_queue.put(_ResultItem(work_id, result=result,\n",
      "  File \"/usr/local/lib/python3.8/dist-packages/joblib/externals/loky/backend/queues.py\", line 239, in put\n",
      "    with self._wlock:\n",
      "  File \"/usr/local/lib/python3.8/dist-packages/joblib/externals/loky/backend/synchronize.py\", line 104, in __enter__\n",
      "    return self._semlock.acquire()\n",
      "KeyboardInterrupt\n",
      "\n",
      "During handling of the above exception, another exception occurred:\n",
      "\n",
      "Traceback (most recent call last):\n",
      "  File \"/usr/lib/python3.8/multiprocessing/process.py\", line 315, in _bootstrap\n",
      "    self.run()\n",
      "  File \"/usr/lib/python3.8/multiprocessing/process.py\", line 108, in run\n",
      "    self._target(*self._args, **self._kwargs)\n",
      "  File \"/usr/local/lib/python3.8/dist-packages/joblib/externals/loky/process_executor.py\", line 423, in _process_worker\n",
      "    _sendback_result(result_queue, call_item.work_id, result=r)\n",
      "  File \"/usr/local/lib/python3.8/dist-packages/joblib/externals/loky/process_executor.py\", line 347, in _sendback_result\n",
      "    result_queue.put(_ResultItem(work_id, exception=exc))\n",
      "  File \"/usr/local/lib/python3.8/dist-packages/joblib/externals/loky/backend/queues.py\", line 239, in put\n",
      "    with self._wlock:\n",
      "  File \"/usr/local/lib/python3.8/dist-packages/joblib/externals/loky/backend/synchronize.py\", line 104, in __enter__\n",
      "    return self._semlock.acquire()\n",
      "KeyboardInterrupt\n",
      "Process LokyProcess-80:\n",
      "Traceback (most recent call last):\n",
      "  File \"/usr/local/lib/python3.8/dist-packages/joblib/externals/loky/process_executor.py\", line 343, in _sendback_result\n",
      "    result_queue.put(_ResultItem(work_id, result=result,\n",
      "  File \"/usr/local/lib/python3.8/dist-packages/joblib/externals/loky/backend/queues.py\", line 239, in put\n",
      "    with self._wlock:\n",
      "  File \"/usr/local/lib/python3.8/dist-packages/joblib/externals/loky/backend/synchronize.py\", line 104, in __enter__\n",
      "    return self._semlock.acquire()\n",
      "KeyboardInterrupt\n",
      "\n",
      "During handling of the above exception, another exception occurred:\n",
      "\n",
      "Traceback (most recent call last):\n",
      "  File \"/usr/lib/python3.8/multiprocessing/process.py\", line 315, in _bootstrap\n",
      "    self.run()\n",
      "  File \"/usr/lib/python3.8/multiprocessing/process.py\", line 108, in run\n",
      "    self._target(*self._args, **self._kwargs)\n",
      "  File \"/usr/local/lib/python3.8/dist-packages/joblib/externals/loky/process_executor.py\", line 423, in _process_worker\n",
      "    _sendback_result(result_queue, call_item.work_id, result=r)\n",
      "  File \"/usr/local/lib/python3.8/dist-packages/joblib/externals/loky/process_executor.py\", line 347, in _sendback_result\n",
      "    result_queue.put(_ResultItem(work_id, exception=exc))\n",
      "  File \"/usr/local/lib/python3.8/dist-packages/joblib/externals/loky/backend/queues.py\", line 239, in put\n",
      "    with self._wlock:\n",
      "  File \"/usr/local/lib/python3.8/dist-packages/joblib/externals/loky/backend/synchronize.py\", line 104, in __enter__\n",
      "    return self._semlock.acquire()\n",
      "KeyboardInterrupt\n",
      "Process LokyProcess-103:\n",
      "Traceback (most recent call last):\n",
      "  File \"/usr/local/lib/python3.8/dist-packages/joblib/externals/loky/process_executor.py\", line 343, in _sendback_result\n",
      "    result_queue.put(_ResultItem(work_id, result=result,\n",
      "  File \"/usr/local/lib/python3.8/dist-packages/joblib/externals/loky/backend/queues.py\", line 239, in put\n",
      "    with self._wlock:\n",
      "  File \"/usr/local/lib/python3.8/dist-packages/joblib/externals/loky/backend/synchronize.py\", line 104, in __enter__\n",
      "    return self._semlock.acquire()\n",
      "KeyboardInterrupt\n",
      "\n",
      "During handling of the above exception, another exception occurred:\n",
      "\n",
      "Traceback (most recent call last):\n",
      "  File \"/usr/lib/python3.8/multiprocessing/process.py\", line 315, in _bootstrap\n",
      "    self.run()\n",
      "  File \"/usr/lib/python3.8/multiprocessing/process.py\", line 108, in run\n",
      "    self._target(*self._args, **self._kwargs)\n",
      "  File \"/usr/local/lib/python3.8/dist-packages/joblib/externals/loky/process_executor.py\", line 423, in _process_worker\n",
      "    _sendback_result(result_queue, call_item.work_id, result=r)\n",
      "  File \"/usr/local/lib/python3.8/dist-packages/joblib/externals/loky/process_executor.py\", line 347, in _sendback_result\n",
      "    result_queue.put(_ResultItem(work_id, exception=exc))\n",
      "  File \"/usr/local/lib/python3.8/dist-packages/joblib/externals/loky/backend/queues.py\", line 239, in put\n",
      "    with self._wlock:\n",
      "  File \"/usr/local/lib/python3.8/dist-packages/joblib/externals/loky/backend/synchronize.py\", line 104, in __enter__\n",
      "    return self._semlock.acquire()\n",
      "KeyboardInterrupt\n",
      "Process LokyProcess-107:\n",
      "Traceback (most recent call last):\n",
      "  File \"/usr/local/lib/python3.8/dist-packages/joblib/externals/loky/process_executor.py\", line 343, in _sendback_result\n",
      "    result_queue.put(_ResultItem(work_id, result=result,\n",
      "  File \"/usr/local/lib/python3.8/dist-packages/joblib/externals/loky/backend/queues.py\", line 239, in put\n",
      "    with self._wlock:\n",
      "  File \"/usr/local/lib/python3.8/dist-packages/joblib/externals/loky/backend/synchronize.py\", line 104, in __enter__\n",
      "    return self._semlock.acquire()\n",
      "KeyboardInterrupt\n",
      "\n",
      "During handling of the above exception, another exception occurred:\n",
      "\n",
      "Traceback (most recent call last):\n",
      "  File \"/usr/lib/python3.8/multiprocessing/process.py\", line 315, in _bootstrap\n",
      "    self.run()\n",
      "  File \"/usr/lib/python3.8/multiprocessing/process.py\", line 108, in run\n",
      "    self._target(*self._args, **self._kwargs)\n",
      "  File \"/usr/local/lib/python3.8/dist-packages/joblib/externals/loky/process_executor.py\", line 423, in _process_worker\n",
      "    _sendback_result(result_queue, call_item.work_id, result=r)\n",
      "  File \"/usr/local/lib/python3.8/dist-packages/joblib/externals/loky/process_executor.py\", line 347, in _sendback_result\n",
      "    result_queue.put(_ResultItem(work_id, exception=exc))\n",
      "  File \"/usr/local/lib/python3.8/dist-packages/joblib/externals/loky/backend/queues.py\", line 239, in put\n",
      "    with self._wlock:\n",
      "  File \"/usr/local/lib/python3.8/dist-packages/joblib/externals/loky/backend/synchronize.py\", line 104, in __enter__\n",
      "    return self._semlock.acquire()\n",
      "KeyboardInterrupt\n",
      "Process LokyProcess-43:\n",
      "Traceback (most recent call last):\n",
      "  File \"/usr/local/lib/python3.8/dist-packages/joblib/externals/loky/process_executor.py\", line 343, in _sendback_result\n",
      "    result_queue.put(_ResultItem(work_id, result=result,\n",
      "  File \"/usr/local/lib/python3.8/dist-packages/joblib/externals/loky/backend/queues.py\", line 239, in put\n",
      "    with self._wlock:\n",
      "  File \"/usr/local/lib/python3.8/dist-packages/joblib/externals/loky/backend/synchronize.py\", line 104, in __enter__\n",
      "    return self._semlock.acquire()\n",
      "KeyboardInterrupt\n",
      "\n",
      "During handling of the above exception, another exception occurred:\n",
      "\n",
      "Traceback (most recent call last):\n",
      "  File \"/usr/lib/python3.8/multiprocessing/process.py\", line 315, in _bootstrap\n",
      "    self.run()\n",
      "  File \"/usr/lib/python3.8/multiprocessing/process.py\", line 108, in run\n",
      "    self._target(*self._args, **self._kwargs)\n",
      "  File \"/usr/local/lib/python3.8/dist-packages/joblib/externals/loky/process_executor.py\", line 423, in _process_worker\n",
      "    _sendback_result(result_queue, call_item.work_id, result=r)\n",
      "  File \"/usr/local/lib/python3.8/dist-packages/joblib/externals/loky/process_executor.py\", line 347, in _sendback_result\n",
      "    result_queue.put(_ResultItem(work_id, exception=exc))\n",
      "  File \"/usr/local/lib/python3.8/dist-packages/joblib/externals/loky/backend/queues.py\", line 239, in put\n",
      "    with self._wlock:\n",
      "  File \"/usr/local/lib/python3.8/dist-packages/joblib/externals/loky/backend/synchronize.py\", line 104, in __enter__\n",
      "    return self._semlock.acquire()\n",
      "KeyboardInterrupt\n",
      "Process LokyProcess-105:\n",
      "Traceback (most recent call last):\n",
      "  File \"/usr/local/lib/python3.8/dist-packages/joblib/externals/loky/process_executor.py\", line 343, in _sendback_result\n",
      "    result_queue.put(_ResultItem(work_id, result=result,\n",
      "  File \"/usr/local/lib/python3.8/dist-packages/joblib/externals/loky/backend/queues.py\", line 239, in put\n",
      "    with self._wlock:\n",
      "  File \"/usr/local/lib/python3.8/dist-packages/joblib/externals/loky/backend/synchronize.py\", line 104, in __enter__\n",
      "    return self._semlock.acquire()\n",
      "KeyboardInterrupt\n",
      "\n",
      "During handling of the above exception, another exception occurred:\n",
      "\n",
      "Traceback (most recent call last):\n",
      "  File \"/usr/lib/python3.8/multiprocessing/process.py\", line 315, in _bootstrap\n",
      "    self.run()\n",
      "  File \"/usr/lib/python3.8/multiprocessing/process.py\", line 108, in run\n",
      "    self._target(*self._args, **self._kwargs)\n",
      "  File \"/usr/local/lib/python3.8/dist-packages/joblib/externals/loky/process_executor.py\", line 423, in _process_worker\n",
      "    _sendback_result(result_queue, call_item.work_id, result=r)\n",
      "  File \"/usr/local/lib/python3.8/dist-packages/joblib/externals/loky/process_executor.py\", line 347, in _sendback_result\n",
      "    result_queue.put(_ResultItem(work_id, exception=exc))\n",
      "  File \"/usr/local/lib/python3.8/dist-packages/joblib/externals/loky/backend/queues.py\", line 239, in put\n",
      "    with self._wlock:\n",
      "  File \"/usr/local/lib/python3.8/dist-packages/joblib/externals/loky/backend/synchronize.py\", line 104, in __enter__\n",
      "    return self._semlock.acquire()\n",
      "KeyboardInterrupt\n",
      "Process LokyProcess-54:\n",
      "Traceback (most recent call last):\n",
      "  File \"/usr/local/lib/python3.8/dist-packages/joblib/externals/loky/process_executor.py\", line 343, in _sendback_result\n",
      "    result_queue.put(_ResultItem(work_id, result=result,\n",
      "  File \"/usr/local/lib/python3.8/dist-packages/joblib/externals/loky/backend/queues.py\", line 239, in put\n",
      "    with self._wlock:\n",
      "  File \"/usr/local/lib/python3.8/dist-packages/joblib/externals/loky/backend/synchronize.py\", line 104, in __enter__\n",
      "    return self._semlock.acquire()\n",
      "KeyboardInterrupt\n",
      "\n",
      "During handling of the above exception, another exception occurred:\n",
      "\n",
      "Traceback (most recent call last):\n",
      "  File \"/usr/lib/python3.8/multiprocessing/process.py\", line 315, in _bootstrap\n",
      "    self.run()\n",
      "  File \"/usr/lib/python3.8/multiprocessing/process.py\", line 108, in run\n",
      "    self._target(*self._args, **self._kwargs)\n",
      "  File \"/usr/local/lib/python3.8/dist-packages/joblib/externals/loky/process_executor.py\", line 423, in _process_worker\n",
      "    _sendback_result(result_queue, call_item.work_id, result=r)\n",
      "  File \"/usr/local/lib/python3.8/dist-packages/joblib/externals/loky/process_executor.py\", line 347, in _sendback_result\n",
      "    result_queue.put(_ResultItem(work_id, exception=exc))\n",
      "  File \"/usr/local/lib/python3.8/dist-packages/joblib/externals/loky/backend/queues.py\", line 239, in put\n",
      "    with self._wlock:\n",
      "  File \"/usr/local/lib/python3.8/dist-packages/joblib/externals/loky/backend/synchronize.py\", line 104, in __enter__\n",
      "    return self._semlock.acquire()\n",
      "KeyboardInterrupt\n",
      "Process LokyProcess-100:\n",
      "Traceback (most recent call last):\n",
      "  File \"/usr/local/lib/python3.8/dist-packages/joblib/externals/loky/process_executor.py\", line 343, in _sendback_result\n",
      "    result_queue.put(_ResultItem(work_id, result=result,\n",
      "  File \"/usr/local/lib/python3.8/dist-packages/joblib/externals/loky/backend/queues.py\", line 239, in put\n",
      "    with self._wlock:\n",
      "  File \"/usr/local/lib/python3.8/dist-packages/joblib/externals/loky/backend/synchronize.py\", line 104, in __enter__\n",
      "    return self._semlock.acquire()\n",
      "KeyboardInterrupt\n",
      "\n",
      "During handling of the above exception, another exception occurred:\n",
      "\n",
      "Traceback (most recent call last):\n",
      "  File \"/usr/lib/python3.8/multiprocessing/process.py\", line 315, in _bootstrap\n",
      "    self.run()\n",
      "  File \"/usr/lib/python3.8/multiprocessing/process.py\", line 108, in run\n",
      "    self._target(*self._args, **self._kwargs)\n",
      "  File \"/usr/local/lib/python3.8/dist-packages/joblib/externals/loky/process_executor.py\", line 423, in _process_worker\n",
      "    _sendback_result(result_queue, call_item.work_id, result=r)\n",
      "  File \"/usr/local/lib/python3.8/dist-packages/joblib/externals/loky/process_executor.py\", line 347, in _sendback_result\n",
      "    result_queue.put(_ResultItem(work_id, exception=exc))\n",
      "  File \"/usr/local/lib/python3.8/dist-packages/joblib/externals/loky/backend/queues.py\", line 239, in put\n",
      "    with self._wlock:\n",
      "  File \"/usr/local/lib/python3.8/dist-packages/joblib/externals/loky/backend/synchronize.py\", line 104, in __enter__\n",
      "    return self._semlock.acquire()\n",
      "KeyboardInterrupt\n",
      "Process LokyProcess-84:\n",
      "Traceback (most recent call last):\n",
      "  File \"/usr/local/lib/python3.8/dist-packages/joblib/externals/loky/process_executor.py\", line 343, in _sendback_result\n",
      "    result_queue.put(_ResultItem(work_id, result=result,\n",
      "  File \"/usr/local/lib/python3.8/dist-packages/joblib/externals/loky/backend/queues.py\", line 239, in put\n",
      "    with self._wlock:\n",
      "  File \"/usr/local/lib/python3.8/dist-packages/joblib/externals/loky/backend/synchronize.py\", line 104, in __enter__\n",
      "    return self._semlock.acquire()\n",
      "KeyboardInterrupt\n",
      "\n",
      "During handling of the above exception, another exception occurred:\n",
      "\n",
      "Traceback (most recent call last):\n",
      "  File \"/usr/lib/python3.8/multiprocessing/process.py\", line 315, in _bootstrap\n",
      "    self.run()\n",
      "  File \"/usr/lib/python3.8/multiprocessing/process.py\", line 108, in run\n",
      "    self._target(*self._args, **self._kwargs)\n",
      "  File \"/usr/local/lib/python3.8/dist-packages/joblib/externals/loky/process_executor.py\", line 423, in _process_worker\n",
      "    _sendback_result(result_queue, call_item.work_id, result=r)\n",
      "  File \"/usr/local/lib/python3.8/dist-packages/joblib/externals/loky/process_executor.py\", line 347, in _sendback_result\n",
      "    result_queue.put(_ResultItem(work_id, exception=exc))\n",
      "  File \"/usr/local/lib/python3.8/dist-packages/joblib/externals/loky/backend/queues.py\", line 239, in put\n",
      "    with self._wlock:\n",
      "  File \"/usr/local/lib/python3.8/dist-packages/joblib/externals/loky/backend/synchronize.py\", line 104, in __enter__\n",
      "    return self._semlock.acquire()\n",
      "KeyboardInterrupt\n",
      "Process LokyProcess-96:\n",
      "Traceback (most recent call last):\n",
      "  File \"/usr/local/lib/python3.8/dist-packages/joblib/externals/loky/process_executor.py\", line 343, in _sendback_result\n",
      "    result_queue.put(_ResultItem(work_id, result=result,\n",
      "  File \"/usr/local/lib/python3.8/dist-packages/joblib/externals/loky/backend/queues.py\", line 239, in put\n",
      "    with self._wlock:\n",
      "  File \"/usr/local/lib/python3.8/dist-packages/joblib/externals/loky/backend/synchronize.py\", line 104, in __enter__\n",
      "    return self._semlock.acquire()\n",
      "KeyboardInterrupt\n",
      "\n",
      "During handling of the above exception, another exception occurred:\n",
      "\n",
      "Traceback (most recent call last):\n",
      "  File \"/usr/lib/python3.8/multiprocessing/process.py\", line 315, in _bootstrap\n",
      "    self.run()\n",
      "  File \"/usr/lib/python3.8/multiprocessing/process.py\", line 108, in run\n",
      "    self._target(*self._args, **self._kwargs)\n",
      "  File \"/usr/local/lib/python3.8/dist-packages/joblib/externals/loky/process_executor.py\", line 423, in _process_worker\n",
      "    _sendback_result(result_queue, call_item.work_id, result=r)\n",
      "  File \"/usr/local/lib/python3.8/dist-packages/joblib/externals/loky/process_executor.py\", line 347, in _sendback_result\n",
      "    result_queue.put(_ResultItem(work_id, exception=exc))\n",
      "  File \"/usr/local/lib/python3.8/dist-packages/joblib/externals/loky/backend/queues.py\", line 239, in put\n",
      "    with self._wlock:\n",
      "  File \"/usr/local/lib/python3.8/dist-packages/joblib/externals/loky/backend/synchronize.py\", line 104, in __enter__\n",
      "    return self._semlock.acquire()\n",
      "KeyboardInterrupt\n",
      "Process LokyProcess-106:\n",
      "Traceback (most recent call last):\n",
      "  File \"/usr/local/lib/python3.8/dist-packages/joblib/externals/loky/process_executor.py\", line 343, in _sendback_result\n",
      "    result_queue.put(_ResultItem(work_id, result=result,\n",
      "  File \"/usr/local/lib/python3.8/dist-packages/joblib/externals/loky/backend/queues.py\", line 239, in put\n",
      "    with self._wlock:\n",
      "  File \"/usr/local/lib/python3.8/dist-packages/joblib/externals/loky/backend/synchronize.py\", line 104, in __enter__\n",
      "    return self._semlock.acquire()\n",
      "KeyboardInterrupt\n",
      "\n",
      "During handling of the above exception, another exception occurred:\n",
      "\n",
      "Traceback (most recent call last):\n",
      "  File \"/usr/lib/python3.8/multiprocessing/process.py\", line 315, in _bootstrap\n",
      "    self.run()\n",
      "  File \"/usr/lib/python3.8/multiprocessing/process.py\", line 108, in run\n",
      "    self._target(*self._args, **self._kwargs)\n",
      "  File \"/usr/local/lib/python3.8/dist-packages/joblib/externals/loky/process_executor.py\", line 423, in _process_worker\n",
      "    _sendback_result(result_queue, call_item.work_id, result=r)\n",
      "  File \"/usr/local/lib/python3.8/dist-packages/joblib/externals/loky/process_executor.py\", line 347, in _sendback_result\n",
      "    result_queue.put(_ResultItem(work_id, exception=exc))\n",
      "  File \"/usr/local/lib/python3.8/dist-packages/joblib/externals/loky/backend/queues.py\", line 239, in put\n",
      "    with self._wlock:\n",
      "  File \"/usr/local/lib/python3.8/dist-packages/joblib/externals/loky/backend/synchronize.py\", line 104, in __enter__\n",
      "    return self._semlock.acquire()\n",
      "KeyboardInterrupt\n",
      "Process LokyProcess-82:\n",
      "Traceback (most recent call last):\n",
      "  File \"/usr/local/lib/python3.8/dist-packages/joblib/externals/loky/process_executor.py\", line 343, in _sendback_result\n",
      "    result_queue.put(_ResultItem(work_id, result=result,\n",
      "  File \"/usr/local/lib/python3.8/dist-packages/joblib/externals/loky/backend/queues.py\", line 239, in put\n",
      "    with self._wlock:\n",
      "  File \"/usr/local/lib/python3.8/dist-packages/joblib/externals/loky/backend/synchronize.py\", line 104, in __enter__\n",
      "    return self._semlock.acquire()\n",
      "KeyboardInterrupt\n",
      "\n",
      "During handling of the above exception, another exception occurred:\n",
      "\n",
      "Traceback (most recent call last):\n",
      "  File \"/usr/lib/python3.8/multiprocessing/process.py\", line 315, in _bootstrap\n",
      "    self.run()\n",
      "  File \"/usr/lib/python3.8/multiprocessing/process.py\", line 108, in run\n",
      "    self._target(*self._args, **self._kwargs)\n",
      "  File \"/usr/local/lib/python3.8/dist-packages/joblib/externals/loky/process_executor.py\", line 423, in _process_worker\n",
      "    _sendback_result(result_queue, call_item.work_id, result=r)\n",
      "  File \"/usr/local/lib/python3.8/dist-packages/joblib/externals/loky/process_executor.py\", line 347, in _sendback_result\n",
      "    result_queue.put(_ResultItem(work_id, exception=exc))\n",
      "  File \"/usr/local/lib/python3.8/dist-packages/joblib/externals/loky/backend/queues.py\", line 239, in put\n",
      "    with self._wlock:\n",
      "  File \"/usr/local/lib/python3.8/dist-packages/joblib/externals/loky/backend/synchronize.py\", line 104, in __enter__\n",
      "    return self._semlock.acquire()\n",
      "KeyboardInterrupt\n",
      "Process LokyProcess-71:\n",
      "Traceback (most recent call last):\n",
      "  File \"/usr/local/lib/python3.8/dist-packages/joblib/externals/loky/process_executor.py\", line 343, in _sendback_result\n",
      "    result_queue.put(_ResultItem(work_id, result=result,\n",
      "  File \"/usr/local/lib/python3.8/dist-packages/joblib/externals/loky/backend/queues.py\", line 239, in put\n",
      "    with self._wlock:\n",
      "  File \"/usr/local/lib/python3.8/dist-packages/joblib/externals/loky/backend/synchronize.py\", line 104, in __enter__\n",
      "    return self._semlock.acquire()\n",
      "KeyboardInterrupt\n",
      "\n",
      "During handling of the above exception, another exception occurred:\n",
      "\n",
      "Traceback (most recent call last):\n",
      "  File \"/usr/lib/python3.8/multiprocessing/process.py\", line 315, in _bootstrap\n",
      "    self.run()\n",
      "  File \"/usr/lib/python3.8/multiprocessing/process.py\", line 108, in run\n",
      "    self._target(*self._args, **self._kwargs)\n",
      "  File \"/usr/local/lib/python3.8/dist-packages/joblib/externals/loky/process_executor.py\", line 423, in _process_worker\n",
      "    _sendback_result(result_queue, call_item.work_id, result=r)\n",
      "  File \"/usr/local/lib/python3.8/dist-packages/joblib/externals/loky/process_executor.py\", line 347, in _sendback_result\n",
      "    result_queue.put(_ResultItem(work_id, exception=exc))\n",
      "  File \"/usr/local/lib/python3.8/dist-packages/joblib/externals/loky/backend/queues.py\", line 239, in put\n",
      "    with self._wlock:\n",
      "  File \"/usr/local/lib/python3.8/dist-packages/joblib/externals/loky/backend/synchronize.py\", line 104, in __enter__\n",
      "    return self._semlock.acquire()\n",
      "KeyboardInterrupt\n",
      "Process LokyProcess-91:\n",
      "Traceback (most recent call last):\n",
      "  File \"/usr/local/lib/python3.8/dist-packages/joblib/externals/loky/process_executor.py\", line 343, in _sendback_result\n",
      "    result_queue.put(_ResultItem(work_id, result=result,\n",
      "  File \"/usr/local/lib/python3.8/dist-packages/joblib/externals/loky/backend/queues.py\", line 239, in put\n",
      "    with self._wlock:\n",
      "  File \"/usr/local/lib/python3.8/dist-packages/joblib/externals/loky/backend/synchronize.py\", line 104, in __enter__\n",
      "    return self._semlock.acquire()\n",
      "KeyboardInterrupt\n",
      "\n",
      "During handling of the above exception, another exception occurred:\n",
      "\n",
      "Traceback (most recent call last):\n",
      "  File \"/usr/lib/python3.8/multiprocessing/process.py\", line 315, in _bootstrap\n",
      "    self.run()\n",
      "  File \"/usr/lib/python3.8/multiprocessing/process.py\", line 108, in run\n",
      "    self._target(*self._args, **self._kwargs)\n",
      "  File \"/usr/local/lib/python3.8/dist-packages/joblib/externals/loky/process_executor.py\", line 423, in _process_worker\n",
      "    _sendback_result(result_queue, call_item.work_id, result=r)\n",
      "  File \"/usr/local/lib/python3.8/dist-packages/joblib/externals/loky/process_executor.py\", line 347, in _sendback_result\n",
      "    result_queue.put(_ResultItem(work_id, exception=exc))\n",
      "  File \"/usr/local/lib/python3.8/dist-packages/joblib/externals/loky/backend/queues.py\", line 239, in put\n",
      "    with self._wlock:\n",
      "  File \"/usr/local/lib/python3.8/dist-packages/joblib/externals/loky/backend/synchronize.py\", line 104, in __enter__\n",
      "    return self._semlock.acquire()\n",
      "KeyboardInterrupt\n",
      "Process LokyProcess-101:\n",
      "Traceback (most recent call last):\n",
      "  File \"/usr/local/lib/python3.8/dist-packages/joblib/externals/loky/process_executor.py\", line 343, in _sendback_result\n",
      "    result_queue.put(_ResultItem(work_id, result=result,\n",
      "  File \"/usr/local/lib/python3.8/dist-packages/joblib/externals/loky/backend/queues.py\", line 239, in put\n",
      "    with self._wlock:\n",
      "  File \"/usr/local/lib/python3.8/dist-packages/joblib/externals/loky/backend/synchronize.py\", line 104, in __enter__\n",
      "    return self._semlock.acquire()\n",
      "KeyboardInterrupt\n",
      "\n",
      "During handling of the above exception, another exception occurred:\n",
      "\n",
      "Traceback (most recent call last):\n",
      "  File \"/usr/lib/python3.8/multiprocessing/process.py\", line 315, in _bootstrap\n",
      "    self.run()\n",
      "  File \"/usr/lib/python3.8/multiprocessing/process.py\", line 108, in run\n",
      "    self._target(*self._args, **self._kwargs)\n",
      "  File \"/usr/local/lib/python3.8/dist-packages/joblib/externals/loky/process_executor.py\", line 423, in _process_worker\n",
      "    _sendback_result(result_queue, call_item.work_id, result=r)\n",
      "  File \"/usr/local/lib/python3.8/dist-packages/joblib/externals/loky/process_executor.py\", line 347, in _sendback_result\n",
      "    result_queue.put(_ResultItem(work_id, exception=exc))\n",
      "  File \"/usr/local/lib/python3.8/dist-packages/joblib/externals/loky/backend/queues.py\", line 239, in put\n",
      "    with self._wlock:\n",
      "  File \"/usr/local/lib/python3.8/dist-packages/joblib/externals/loky/backend/synchronize.py\", line 104, in __enter__\n",
      "    return self._semlock.acquire()\n",
      "KeyboardInterrupt\n",
      "Process LokyProcess-12:\n",
      "Traceback (most recent call last):\n",
      "  File \"/usr/local/lib/python3.8/dist-packages/joblib/externals/loky/process_executor.py\", line 343, in _sendback_result\n",
      "    result_queue.put(_ResultItem(work_id, result=result,\n",
      "  File \"/usr/local/lib/python3.8/dist-packages/joblib/externals/loky/backend/queues.py\", line 239, in put\n",
      "    with self._wlock:\n",
      "  File \"/usr/local/lib/python3.8/dist-packages/joblib/externals/loky/backend/synchronize.py\", line 104, in __enter__\n",
      "    return self._semlock.acquire()\n",
      "KeyboardInterrupt\n",
      "\n",
      "During handling of the above exception, another exception occurred:\n",
      "\n",
      "Traceback (most recent call last):\n",
      "  File \"/usr/lib/python3.8/multiprocessing/process.py\", line 315, in _bootstrap\n",
      "    self.run()\n",
      "  File \"/usr/lib/python3.8/multiprocessing/process.py\", line 108, in run\n",
      "    self._target(*self._args, **self._kwargs)\n",
      "  File \"/usr/local/lib/python3.8/dist-packages/joblib/externals/loky/process_executor.py\", line 423, in _process_worker\n",
      "    _sendback_result(result_queue, call_item.work_id, result=r)\n",
      "  File \"/usr/local/lib/python3.8/dist-packages/joblib/externals/loky/process_executor.py\", line 347, in _sendback_result\n",
      "    result_queue.put(_ResultItem(work_id, exception=exc))\n",
      "  File \"/usr/local/lib/python3.8/dist-packages/joblib/externals/loky/backend/queues.py\", line 239, in put\n",
      "    with self._wlock:\n",
      "  File \"/usr/local/lib/python3.8/dist-packages/joblib/externals/loky/backend/synchronize.py\", line 104, in __enter__\n",
      "    return self._semlock.acquire()\n",
      "KeyboardInterrupt\n",
      "Process LokyProcess-1:\n",
      "Traceback (most recent call last):\n",
      "  File \"/usr/local/lib/python3.8/dist-packages/joblib/externals/loky/process_executor.py\", line 343, in _sendback_result\n",
      "    result_queue.put(_ResultItem(work_id, result=result,\n",
      "  File \"/usr/local/lib/python3.8/dist-packages/joblib/externals/loky/backend/queues.py\", line 239, in put\n",
      "    with self._wlock:\n",
      "  File \"/usr/local/lib/python3.8/dist-packages/joblib/externals/loky/backend/synchronize.py\", line 104, in __enter__\n",
      "    return self._semlock.acquire()\n",
      "KeyboardInterrupt\n",
      "\n",
      "During handling of the above exception, another exception occurred:\n",
      "\n",
      "Traceback (most recent call last):\n",
      "  File \"/usr/lib/python3.8/multiprocessing/process.py\", line 315, in _bootstrap\n",
      "    self.run()\n",
      "  File \"/usr/lib/python3.8/multiprocessing/process.py\", line 108, in run\n",
      "    self._target(*self._args, **self._kwargs)\n",
      "  File \"/usr/local/lib/python3.8/dist-packages/joblib/externals/loky/process_executor.py\", line 423, in _process_worker\n",
      "    _sendback_result(result_queue, call_item.work_id, result=r)\n",
      "  File \"/usr/local/lib/python3.8/dist-packages/joblib/externals/loky/process_executor.py\", line 347, in _sendback_result\n",
      "    result_queue.put(_ResultItem(work_id, exception=exc))\n",
      "  File \"/usr/local/lib/python3.8/dist-packages/joblib/externals/loky/backend/queues.py\", line 239, in put\n",
      "    with self._wlock:\n",
      "  File \"/usr/local/lib/python3.8/dist-packages/joblib/externals/loky/backend/synchronize.py\", line 104, in __enter__\n",
      "    return self._semlock.acquire()\n",
      "KeyboardInterrupt\n",
      "Process LokyProcess-44:\n",
      "Traceback (most recent call last):\n",
      "  File \"/usr/local/lib/python3.8/dist-packages/joblib/externals/loky/process_executor.py\", line 343, in _sendback_result\n",
      "    result_queue.put(_ResultItem(work_id, result=result,\n",
      "  File \"/usr/local/lib/python3.8/dist-packages/joblib/externals/loky/backend/queues.py\", line 239, in put\n",
      "    with self._wlock:\n",
      "  File \"/usr/local/lib/python3.8/dist-packages/joblib/externals/loky/backend/synchronize.py\", line 104, in __enter__\n",
      "    return self._semlock.acquire()\n",
      "KeyboardInterrupt\n",
      "\n",
      "During handling of the above exception, another exception occurred:\n",
      "\n",
      "Traceback (most recent call last):\n",
      "  File \"/usr/lib/python3.8/multiprocessing/process.py\", line 315, in _bootstrap\n",
      "    self.run()\n",
      "  File \"/usr/lib/python3.8/multiprocessing/process.py\", line 108, in run\n",
      "    self._target(*self._args, **self._kwargs)\n",
      "  File \"/usr/local/lib/python3.8/dist-packages/joblib/externals/loky/process_executor.py\", line 423, in _process_worker\n",
      "    _sendback_result(result_queue, call_item.work_id, result=r)\n",
      "  File \"/usr/local/lib/python3.8/dist-packages/joblib/externals/loky/process_executor.py\", line 347, in _sendback_result\n",
      "    result_queue.put(_ResultItem(work_id, exception=exc))\n",
      "  File \"/usr/local/lib/python3.8/dist-packages/joblib/externals/loky/backend/queues.py\", line 239, in put\n",
      "    with self._wlock:\n",
      "  File \"/usr/local/lib/python3.8/dist-packages/joblib/externals/loky/backend/synchronize.py\", line 104, in __enter__\n",
      "    return self._semlock.acquire()\n",
      "KeyboardInterrupt\n",
      "Process LokyProcess-23:\n",
      "Traceback (most recent call last):\n",
      "  File \"/usr/local/lib/python3.8/dist-packages/joblib/externals/loky/process_executor.py\", line 343, in _sendback_result\n",
      "    result_queue.put(_ResultItem(work_id, result=result,\n",
      "  File \"/usr/local/lib/python3.8/dist-packages/joblib/externals/loky/backend/queues.py\", line 239, in put\n",
      "    with self._wlock:\n",
      "  File \"/usr/local/lib/python3.8/dist-packages/joblib/externals/loky/backend/synchronize.py\", line 104, in __enter__\n",
      "    return self._semlock.acquire()\n",
      "KeyboardInterrupt\n",
      "\n",
      "During handling of the above exception, another exception occurred:\n",
      "\n",
      "Traceback (most recent call last):\n",
      "  File \"/usr/lib/python3.8/multiprocessing/process.py\", line 315, in _bootstrap\n",
      "    self.run()\n",
      "  File \"/usr/lib/python3.8/multiprocessing/process.py\", line 108, in run\n",
      "    self._target(*self._args, **self._kwargs)\n",
      "  File \"/usr/local/lib/python3.8/dist-packages/joblib/externals/loky/process_executor.py\", line 423, in _process_worker\n",
      "    _sendback_result(result_queue, call_item.work_id, result=r)\n",
      "  File \"/usr/local/lib/python3.8/dist-packages/joblib/externals/loky/process_executor.py\", line 347, in _sendback_result\n",
      "    result_queue.put(_ResultItem(work_id, exception=exc))\n",
      "  File \"/usr/local/lib/python3.8/dist-packages/joblib/externals/loky/backend/queues.py\", line 239, in put\n",
      "    with self._wlock:\n",
      "  File \"/usr/local/lib/python3.8/dist-packages/joblib/externals/loky/backend/synchronize.py\", line 104, in __enter__\n",
      "    return self._semlock.acquire()\n",
      "KeyboardInterrupt\n",
      "Process LokyProcess-74:\n",
      "Traceback (most recent call last):\n",
      "  File \"/usr/local/lib/python3.8/dist-packages/joblib/externals/loky/process_executor.py\", line 343, in _sendback_result\n",
      "    result_queue.put(_ResultItem(work_id, result=result,\n",
      "  File \"/usr/local/lib/python3.8/dist-packages/joblib/externals/loky/backend/queues.py\", line 239, in put\n",
      "    with self._wlock:\n",
      "  File \"/usr/local/lib/python3.8/dist-packages/joblib/externals/loky/backend/synchronize.py\", line 104, in __enter__\n",
      "    return self._semlock.acquire()\n",
      "KeyboardInterrupt\n",
      "\n",
      "During handling of the above exception, another exception occurred:\n",
      "\n",
      "Traceback (most recent call last):\n",
      "  File \"/usr/lib/python3.8/multiprocessing/process.py\", line 315, in _bootstrap\n",
      "    self.run()\n",
      "  File \"/usr/lib/python3.8/multiprocessing/process.py\", line 108, in run\n",
      "    self._target(*self._args, **self._kwargs)\n",
      "  File \"/usr/local/lib/python3.8/dist-packages/joblib/externals/loky/process_executor.py\", line 423, in _process_worker\n",
      "    _sendback_result(result_queue, call_item.work_id, result=r)\n",
      "  File \"/usr/local/lib/python3.8/dist-packages/joblib/externals/loky/process_executor.py\", line 347, in _sendback_result\n",
      "    result_queue.put(_ResultItem(work_id, exception=exc))\n",
      "  File \"/usr/local/lib/python3.8/dist-packages/joblib/externals/loky/backend/queues.py\", line 239, in put\n",
      "    with self._wlock:\n",
      "  File \"/usr/local/lib/python3.8/dist-packages/joblib/externals/loky/backend/synchronize.py\", line 104, in __enter__\n",
      "    return self._semlock.acquire()\n",
      "KeyboardInterrupt\n",
      "Process LokyProcess-104:\n",
      "Traceback (most recent call last):\n",
      "  File \"/usr/local/lib/python3.8/dist-packages/joblib/externals/loky/process_executor.py\", line 343, in _sendback_result\n",
      "    result_queue.put(_ResultItem(work_id, result=result,\n",
      "  File \"/usr/local/lib/python3.8/dist-packages/joblib/externals/loky/backend/queues.py\", line 239, in put\n",
      "    with self._wlock:\n",
      "  File \"/usr/local/lib/python3.8/dist-packages/joblib/externals/loky/backend/synchronize.py\", line 104, in __enter__\n",
      "    return self._semlock.acquire()\n",
      "KeyboardInterrupt\n",
      "\n",
      "During handling of the above exception, another exception occurred:\n",
      "\n",
      "Traceback (most recent call last):\n",
      "  File \"/usr/lib/python3.8/multiprocessing/process.py\", line 315, in _bootstrap\n",
      "    self.run()\n",
      "  File \"/usr/lib/python3.8/multiprocessing/process.py\", line 108, in run\n",
      "    self._target(*self._args, **self._kwargs)\n",
      "  File \"/usr/local/lib/python3.8/dist-packages/joblib/externals/loky/process_executor.py\", line 423, in _process_worker\n",
      "    _sendback_result(result_queue, call_item.work_id, result=r)\n",
      "  File \"/usr/local/lib/python3.8/dist-packages/joblib/externals/loky/process_executor.py\", line 347, in _sendback_result\n",
      "    result_queue.put(_ResultItem(work_id, exception=exc))\n",
      "  File \"/usr/local/lib/python3.8/dist-packages/joblib/externals/loky/backend/queues.py\", line 239, in put\n",
      "    with self._wlock:\n",
      "  File \"/usr/local/lib/python3.8/dist-packages/joblib/externals/loky/backend/synchronize.py\", line 104, in __enter__\n",
      "    return self._semlock.acquire()\n",
      "KeyboardInterrupt\n",
      "Process LokyProcess-42:\n",
      "Traceback (most recent call last):\n",
      "  File \"/usr/local/lib/python3.8/dist-packages/joblib/externals/loky/process_executor.py\", line 343, in _sendback_result\n",
      "    result_queue.put(_ResultItem(work_id, result=result,\n",
      "  File \"/usr/local/lib/python3.8/dist-packages/joblib/externals/loky/backend/queues.py\", line 239, in put\n",
      "    with self._wlock:\n",
      "  File \"/usr/local/lib/python3.8/dist-packages/joblib/externals/loky/backend/synchronize.py\", line 104, in __enter__\n",
      "    return self._semlock.acquire()\n",
      "KeyboardInterrupt\n",
      "\n",
      "During handling of the above exception, another exception occurred:\n",
      "\n",
      "Traceback (most recent call last):\n",
      "  File \"/usr/lib/python3.8/multiprocessing/process.py\", line 315, in _bootstrap\n",
      "    self.run()\n",
      "  File \"/usr/lib/python3.8/multiprocessing/process.py\", line 108, in run\n",
      "    self._target(*self._args, **self._kwargs)\n",
      "  File \"/usr/local/lib/python3.8/dist-packages/joblib/externals/loky/process_executor.py\", line 423, in _process_worker\n",
      "    _sendback_result(result_queue, call_item.work_id, result=r)\n",
      "  File \"/usr/local/lib/python3.8/dist-packages/joblib/externals/loky/process_executor.py\", line 347, in _sendback_result\n",
      "    result_queue.put(_ResultItem(work_id, exception=exc))\n",
      "  File \"/usr/local/lib/python3.8/dist-packages/joblib/externals/loky/backend/queues.py\", line 239, in put\n",
      "    with self._wlock:\n",
      "  File \"/usr/local/lib/python3.8/dist-packages/joblib/externals/loky/backend/synchronize.py\", line 104, in __enter__\n",
      "    return self._semlock.acquire()\n",
      "KeyboardInterrupt\n",
      "Process LokyProcess-60:\n",
      "Traceback (most recent call last):\n",
      "  File \"/usr/local/lib/python3.8/dist-packages/joblib/externals/loky/process_executor.py\", line 343, in _sendback_result\n",
      "    result_queue.put(_ResultItem(work_id, result=result,\n",
      "  File \"/usr/local/lib/python3.8/dist-packages/joblib/externals/loky/backend/queues.py\", line 239, in put\n",
      "    with self._wlock:\n",
      "  File \"/usr/local/lib/python3.8/dist-packages/joblib/externals/loky/backend/synchronize.py\", line 104, in __enter__\n",
      "    return self._semlock.acquire()\n",
      "KeyboardInterrupt\n",
      "\n",
      "During handling of the above exception, another exception occurred:\n",
      "\n",
      "Traceback (most recent call last):\n",
      "  File \"/usr/lib/python3.8/multiprocessing/process.py\", line 315, in _bootstrap\n",
      "    self.run()\n",
      "  File \"/usr/lib/python3.8/multiprocessing/process.py\", line 108, in run\n",
      "    self._target(*self._args, **self._kwargs)\n",
      "  File \"/usr/local/lib/python3.8/dist-packages/joblib/externals/loky/process_executor.py\", line 423, in _process_worker\n",
      "    _sendback_result(result_queue, call_item.work_id, result=r)\n",
      "  File \"/usr/local/lib/python3.8/dist-packages/joblib/externals/loky/process_executor.py\", line 347, in _sendback_result\n",
      "    result_queue.put(_ResultItem(work_id, exception=exc))\n",
      "  File \"/usr/local/lib/python3.8/dist-packages/joblib/externals/loky/backend/queues.py\", line 239, in put\n",
      "    with self._wlock:\n",
      "  File \"/usr/local/lib/python3.8/dist-packages/joblib/externals/loky/backend/synchronize.py\", line 104, in __enter__\n",
      "    return self._semlock.acquire()\n",
      "KeyboardInterrupt\n",
      "Process LokyProcess-78:\n",
      "Traceback (most recent call last):\n",
      "  File \"/usr/local/lib/python3.8/dist-packages/joblib/externals/loky/process_executor.py\", line 343, in _sendback_result\n",
      "    result_queue.put(_ResultItem(work_id, result=result,\n",
      "  File \"/usr/local/lib/python3.8/dist-packages/joblib/externals/loky/backend/queues.py\", line 239, in put\n",
      "    with self._wlock:\n",
      "  File \"/usr/local/lib/python3.8/dist-packages/joblib/externals/loky/backend/synchronize.py\", line 104, in __enter__\n",
      "    return self._semlock.acquire()\n",
      "KeyboardInterrupt\n",
      "\n",
      "During handling of the above exception, another exception occurred:\n",
      "\n",
      "Traceback (most recent call last):\n",
      "  File \"/usr/lib/python3.8/multiprocessing/process.py\", line 315, in _bootstrap\n",
      "    self.run()\n",
      "  File \"/usr/lib/python3.8/multiprocessing/process.py\", line 108, in run\n",
      "    self._target(*self._args, **self._kwargs)\n",
      "  File \"/usr/local/lib/python3.8/dist-packages/joblib/externals/loky/process_executor.py\", line 423, in _process_worker\n",
      "    _sendback_result(result_queue, call_item.work_id, result=r)\n",
      "  File \"/usr/local/lib/python3.8/dist-packages/joblib/externals/loky/process_executor.py\", line 347, in _sendback_result\n",
      "    result_queue.put(_ResultItem(work_id, exception=exc))\n",
      "  File \"/usr/local/lib/python3.8/dist-packages/joblib/externals/loky/backend/queues.py\", line 239, in put\n",
      "    with self._wlock:\n",
      "  File \"/usr/local/lib/python3.8/dist-packages/joblib/externals/loky/backend/synchronize.py\", line 104, in __enter__\n",
      "    return self._semlock.acquire()\n",
      "KeyboardInterrupt\n",
      "Process LokyProcess-65:\n",
      "Traceback (most recent call last):\n",
      "  File \"/usr/local/lib/python3.8/dist-packages/joblib/externals/loky/process_executor.py\", line 343, in _sendback_result\n",
      "    result_queue.put(_ResultItem(work_id, result=result,\n",
      "  File \"/usr/local/lib/python3.8/dist-packages/joblib/externals/loky/backend/queues.py\", line 239, in put\n",
      "    with self._wlock:\n",
      "  File \"/usr/local/lib/python3.8/dist-packages/joblib/externals/loky/backend/synchronize.py\", line 104, in __enter__\n",
      "    return self._semlock.acquire()\n",
      "KeyboardInterrupt\n",
      "\n",
      "During handling of the above exception, another exception occurred:\n",
      "\n",
      "Traceback (most recent call last):\n",
      "  File \"/usr/lib/python3.8/multiprocessing/process.py\", line 315, in _bootstrap\n",
      "    self.run()\n",
      "  File \"/usr/lib/python3.8/multiprocessing/process.py\", line 108, in run\n",
      "    self._target(*self._args, **self._kwargs)\n",
      "  File \"/usr/local/lib/python3.8/dist-packages/joblib/externals/loky/process_executor.py\", line 423, in _process_worker\n",
      "    _sendback_result(result_queue, call_item.work_id, result=r)\n",
      "  File \"/usr/local/lib/python3.8/dist-packages/joblib/externals/loky/process_executor.py\", line 347, in _sendback_result\n",
      "    result_queue.put(_ResultItem(work_id, exception=exc))\n",
      "  File \"/usr/local/lib/python3.8/dist-packages/joblib/externals/loky/backend/queues.py\", line 239, in put\n",
      "    with self._wlock:\n",
      "  File \"/usr/local/lib/python3.8/dist-packages/joblib/externals/loky/backend/synchronize.py\", line 104, in __enter__\n",
      "    return self._semlock.acquire()\n",
      "KeyboardInterrupt\n",
      "Process LokyProcess-22:\n",
      "Traceback (most recent call last):\n",
      "  File \"/usr/local/lib/python3.8/dist-packages/joblib/externals/loky/process_executor.py\", line 343, in _sendback_result\n",
      "    result_queue.put(_ResultItem(work_id, result=result,\n",
      "  File \"/usr/local/lib/python3.8/dist-packages/joblib/externals/loky/backend/queues.py\", line 239, in put\n",
      "    with self._wlock:\n",
      "  File \"/usr/local/lib/python3.8/dist-packages/joblib/externals/loky/backend/synchronize.py\", line 104, in __enter__\n",
      "    return self._semlock.acquire()\n",
      "KeyboardInterrupt\n",
      "\n",
      "During handling of the above exception, another exception occurred:\n",
      "\n",
      "Traceback (most recent call last):\n",
      "  File \"/usr/lib/python3.8/multiprocessing/process.py\", line 315, in _bootstrap\n",
      "    self.run()\n",
      "  File \"/usr/lib/python3.8/multiprocessing/process.py\", line 108, in run\n",
      "    self._target(*self._args, **self._kwargs)\n",
      "  File \"/usr/local/lib/python3.8/dist-packages/joblib/externals/loky/process_executor.py\", line 423, in _process_worker\n",
      "    _sendback_result(result_queue, call_item.work_id, result=r)\n",
      "  File \"/usr/local/lib/python3.8/dist-packages/joblib/externals/loky/process_executor.py\", line 347, in _sendback_result\n",
      "    result_queue.put(_ResultItem(work_id, exception=exc))\n",
      "  File \"/usr/local/lib/python3.8/dist-packages/joblib/externals/loky/backend/queues.py\", line 239, in put\n",
      "    with self._wlock:\n",
      "  File \"/usr/local/lib/python3.8/dist-packages/joblib/externals/loky/backend/synchronize.py\", line 104, in __enter__\n",
      "    return self._semlock.acquire()\n",
      "KeyboardInterrupt\n",
      "Process LokyProcess-77:\n",
      "Traceback (most recent call last):\n",
      "  File \"/usr/local/lib/python3.8/dist-packages/joblib/externals/loky/process_executor.py\", line 343, in _sendback_result\n",
      "    result_queue.put(_ResultItem(work_id, result=result,\n",
      "  File \"/usr/local/lib/python3.8/dist-packages/joblib/externals/loky/backend/queues.py\", line 239, in put\n",
      "    with self._wlock:\n",
      "  File \"/usr/local/lib/python3.8/dist-packages/joblib/externals/loky/backend/synchronize.py\", line 104, in __enter__\n",
      "    return self._semlock.acquire()\n",
      "KeyboardInterrupt\n",
      "\n",
      "During handling of the above exception, another exception occurred:\n",
      "\n",
      "Traceback (most recent call last):\n",
      "  File \"/usr/lib/python3.8/multiprocessing/process.py\", line 315, in _bootstrap\n",
      "    self.run()\n",
      "  File \"/usr/lib/python3.8/multiprocessing/process.py\", line 108, in run\n",
      "    self._target(*self._args, **self._kwargs)\n",
      "  File \"/usr/local/lib/python3.8/dist-packages/joblib/externals/loky/process_executor.py\", line 423, in _process_worker\n",
      "    _sendback_result(result_queue, call_item.work_id, result=r)\n",
      "  File \"/usr/local/lib/python3.8/dist-packages/joblib/externals/loky/process_executor.py\", line 347, in _sendback_result\n",
      "    result_queue.put(_ResultItem(work_id, exception=exc))\n",
      "  File \"/usr/local/lib/python3.8/dist-packages/joblib/externals/loky/backend/queues.py\", line 239, in put\n",
      "    with self._wlock:\n",
      "  File \"/usr/local/lib/python3.8/dist-packages/joblib/externals/loky/backend/synchronize.py\", line 104, in __enter__\n",
      "    return self._semlock.acquire()\n",
      "KeyboardInterrupt\n",
      "Process LokyProcess-62:\n",
      "Traceback (most recent call last):\n",
      "  File \"/usr/local/lib/python3.8/dist-packages/joblib/externals/loky/process_executor.py\", line 343, in _sendback_result\n",
      "    result_queue.put(_ResultItem(work_id, result=result,\n",
      "  File \"/usr/local/lib/python3.8/dist-packages/joblib/externals/loky/backend/queues.py\", line 239, in put\n",
      "    with self._wlock:\n",
      "  File \"/usr/local/lib/python3.8/dist-packages/joblib/externals/loky/backend/synchronize.py\", line 104, in __enter__\n",
      "    return self._semlock.acquire()\n",
      "KeyboardInterrupt\n",
      "\n",
      "During handling of the above exception, another exception occurred:\n",
      "\n",
      "Traceback (most recent call last):\n",
      "  File \"/usr/lib/python3.8/multiprocessing/process.py\", line 315, in _bootstrap\n",
      "    self.run()\n",
      "  File \"/usr/lib/python3.8/multiprocessing/process.py\", line 108, in run\n",
      "    self._target(*self._args, **self._kwargs)\n",
      "  File \"/usr/local/lib/python3.8/dist-packages/joblib/externals/loky/process_executor.py\", line 423, in _process_worker\n",
      "    _sendback_result(result_queue, call_item.work_id, result=r)\n",
      "  File \"/usr/local/lib/python3.8/dist-packages/joblib/externals/loky/process_executor.py\", line 347, in _sendback_result\n",
      "    result_queue.put(_ResultItem(work_id, exception=exc))\n",
      "  File \"/usr/local/lib/python3.8/dist-packages/joblib/externals/loky/backend/queues.py\", line 239, in put\n",
      "    with self._wlock:\n",
      "  File \"/usr/local/lib/python3.8/dist-packages/joblib/externals/loky/backend/synchronize.py\", line 104, in __enter__\n",
      "    return self._semlock.acquire()\n",
      "KeyboardInterrupt\n",
      "Process LokyProcess-98:\n",
      "Traceback (most recent call last):\n",
      "  File \"/usr/local/lib/python3.8/dist-packages/joblib/externals/loky/process_executor.py\", line 343, in _sendback_result\n",
      "    result_queue.put(_ResultItem(work_id, result=result,\n",
      "  File \"/usr/local/lib/python3.8/dist-packages/joblib/externals/loky/backend/queues.py\", line 239, in put\n",
      "    with self._wlock:\n",
      "  File \"/usr/local/lib/python3.8/dist-packages/joblib/externals/loky/backend/synchronize.py\", line 104, in __enter__\n",
      "    return self._semlock.acquire()\n",
      "KeyboardInterrupt\n",
      "\n",
      "During handling of the above exception, another exception occurred:\n",
      "\n",
      "Traceback (most recent call last):\n",
      "  File \"/usr/lib/python3.8/multiprocessing/process.py\", line 315, in _bootstrap\n",
      "    self.run()\n",
      "  File \"/usr/lib/python3.8/multiprocessing/process.py\", line 108, in run\n",
      "    self._target(*self._args, **self._kwargs)\n",
      "  File \"/usr/local/lib/python3.8/dist-packages/joblib/externals/loky/process_executor.py\", line 423, in _process_worker\n",
      "    _sendback_result(result_queue, call_item.work_id, result=r)\n",
      "  File \"/usr/local/lib/python3.8/dist-packages/joblib/externals/loky/process_executor.py\", line 347, in _sendback_result\n",
      "    result_queue.put(_ResultItem(work_id, exception=exc))\n",
      "  File \"/usr/local/lib/python3.8/dist-packages/joblib/externals/loky/backend/queues.py\", line 239, in put\n",
      "    with self._wlock:\n",
      "  File \"/usr/local/lib/python3.8/dist-packages/joblib/externals/loky/backend/synchronize.py\", line 104, in __enter__\n",
      "    return self._semlock.acquire()\n",
      "KeyboardInterrupt\n",
      "Process LokyProcess-73:\n",
      "Traceback (most recent call last):\n",
      "  File \"/usr/local/lib/python3.8/dist-packages/joblib/externals/loky/process_executor.py\", line 343, in _sendback_result\n",
      "    result_queue.put(_ResultItem(work_id, result=result,\n",
      "  File \"/usr/local/lib/python3.8/dist-packages/joblib/externals/loky/backend/queues.py\", line 239, in put\n",
      "    with self._wlock:\n",
      "  File \"/usr/local/lib/python3.8/dist-packages/joblib/externals/loky/backend/synchronize.py\", line 104, in __enter__\n",
      "    return self._semlock.acquire()\n",
      "KeyboardInterrupt\n",
      "\n",
      "During handling of the above exception, another exception occurred:\n",
      "\n",
      "Traceback (most recent call last):\n",
      "  File \"/usr/lib/python3.8/multiprocessing/process.py\", line 315, in _bootstrap\n",
      "    self.run()\n",
      "  File \"/usr/lib/python3.8/multiprocessing/process.py\", line 108, in run\n",
      "    self._target(*self._args, **self._kwargs)\n",
      "  File \"/usr/local/lib/python3.8/dist-packages/joblib/externals/loky/process_executor.py\", line 423, in _process_worker\n",
      "    _sendback_result(result_queue, call_item.work_id, result=r)\n",
      "  File \"/usr/local/lib/python3.8/dist-packages/joblib/externals/loky/process_executor.py\", line 347, in _sendback_result\n",
      "    result_queue.put(_ResultItem(work_id, exception=exc))\n",
      "  File \"/usr/local/lib/python3.8/dist-packages/joblib/externals/loky/backend/queues.py\", line 239, in put\n",
      "    with self._wlock:\n",
      "  File \"/usr/local/lib/python3.8/dist-packages/joblib/externals/loky/backend/synchronize.py\", line 104, in __enter__\n",
      "    return self._semlock.acquire()\n",
      "KeyboardInterrupt\n",
      "Process LokyProcess-92:\n",
      "Traceback (most recent call last):\n",
      "  File \"/usr/local/lib/python3.8/dist-packages/joblib/externals/loky/process_executor.py\", line 343, in _sendback_result\n",
      "    result_queue.put(_ResultItem(work_id, result=result,\n",
      "  File \"/usr/local/lib/python3.8/dist-packages/joblib/externals/loky/backend/queues.py\", line 239, in put\n",
      "    with self._wlock:\n",
      "  File \"/usr/local/lib/python3.8/dist-packages/joblib/externals/loky/backend/synchronize.py\", line 104, in __enter__\n",
      "    return self._semlock.acquire()\n",
      "KeyboardInterrupt\n",
      "\n",
      "During handling of the above exception, another exception occurred:\n",
      "\n",
      "Traceback (most recent call last):\n",
      "  File \"/usr/lib/python3.8/multiprocessing/process.py\", line 315, in _bootstrap\n",
      "    self.run()\n",
      "  File \"/usr/lib/python3.8/multiprocessing/process.py\", line 108, in run\n",
      "    self._target(*self._args, **self._kwargs)\n",
      "  File \"/usr/local/lib/python3.8/dist-packages/joblib/externals/loky/process_executor.py\", line 423, in _process_worker\n",
      "    _sendback_result(result_queue, call_item.work_id, result=r)\n",
      "  File \"/usr/local/lib/python3.8/dist-packages/joblib/externals/loky/process_executor.py\", line 347, in _sendback_result\n",
      "    result_queue.put(_ResultItem(work_id, exception=exc))\n",
      "  File \"/usr/local/lib/python3.8/dist-packages/joblib/externals/loky/backend/queues.py\", line 239, in put\n",
      "    with self._wlock:\n",
      "  File \"/usr/local/lib/python3.8/dist-packages/joblib/externals/loky/backend/synchronize.py\", line 104, in __enter__\n",
      "    return self._semlock.acquire()\n",
      "KeyboardInterrupt\n",
      "Process LokyProcess-95:\n",
      "Traceback (most recent call last):\n",
      "  File \"/usr/local/lib/python3.8/dist-packages/joblib/externals/loky/process_executor.py\", line 343, in _sendback_result\n",
      "    result_queue.put(_ResultItem(work_id, result=result,\n",
      "  File \"/usr/local/lib/python3.8/dist-packages/joblib/externals/loky/backend/queues.py\", line 239, in put\n",
      "    with self._wlock:\n",
      "  File \"/usr/local/lib/python3.8/dist-packages/joblib/externals/loky/backend/synchronize.py\", line 104, in __enter__\n",
      "    return self._semlock.acquire()\n",
      "KeyboardInterrupt\n",
      "\n",
      "During handling of the above exception, another exception occurred:\n",
      "\n",
      "Traceback (most recent call last):\n",
      "  File \"/usr/lib/python3.8/multiprocessing/process.py\", line 315, in _bootstrap\n",
      "    self.run()\n",
      "  File \"/usr/lib/python3.8/multiprocessing/process.py\", line 108, in run\n",
      "    self._target(*self._args, **self._kwargs)\n",
      "  File \"/usr/local/lib/python3.8/dist-packages/joblib/externals/loky/process_executor.py\", line 423, in _process_worker\n",
      "    _sendback_result(result_queue, call_item.work_id, result=r)\n",
      "  File \"/usr/local/lib/python3.8/dist-packages/joblib/externals/loky/process_executor.py\", line 347, in _sendback_result\n",
      "    result_queue.put(_ResultItem(work_id, exception=exc))\n",
      "  File \"/usr/local/lib/python3.8/dist-packages/joblib/externals/loky/backend/queues.py\", line 239, in put\n",
      "    with self._wlock:\n",
      "  File \"/usr/local/lib/python3.8/dist-packages/joblib/externals/loky/backend/synchronize.py\", line 104, in __enter__\n",
      "    return self._semlock.acquire()\n",
      "KeyboardInterrupt\n",
      "Process LokyProcess-57:\n",
      "Traceback (most recent call last):\n",
      "  File \"/usr/local/lib/python3.8/dist-packages/joblib/externals/loky/process_executor.py\", line 343, in _sendback_result\n",
      "    result_queue.put(_ResultItem(work_id, result=result,\n",
      "  File \"/usr/local/lib/python3.8/dist-packages/joblib/externals/loky/backend/queues.py\", line 239, in put\n",
      "    with self._wlock:\n",
      "  File \"/usr/local/lib/python3.8/dist-packages/joblib/externals/loky/backend/synchronize.py\", line 104, in __enter__\n",
      "    return self._semlock.acquire()\n",
      "KeyboardInterrupt\n",
      "\n",
      "During handling of the above exception, another exception occurred:\n",
      "\n",
      "Traceback (most recent call last):\n",
      "  File \"/usr/lib/python3.8/multiprocessing/process.py\", line 315, in _bootstrap\n",
      "    self.run()\n",
      "  File \"/usr/lib/python3.8/multiprocessing/process.py\", line 108, in run\n",
      "    self._target(*self._args, **self._kwargs)\n",
      "  File \"/usr/local/lib/python3.8/dist-packages/joblib/externals/loky/process_executor.py\", line 423, in _process_worker\n",
      "    _sendback_result(result_queue, call_item.work_id, result=r)\n",
      "  File \"/usr/local/lib/python3.8/dist-packages/joblib/externals/loky/process_executor.py\", line 347, in _sendback_result\n",
      "    result_queue.put(_ResultItem(work_id, exception=exc))\n",
      "  File \"/usr/local/lib/python3.8/dist-packages/joblib/externals/loky/backend/queues.py\", line 239, in put\n",
      "    with self._wlock:\n",
      "  File \"/usr/local/lib/python3.8/dist-packages/joblib/externals/loky/backend/synchronize.py\", line 104, in __enter__\n",
      "    return self._semlock.acquire()\n",
      "KeyboardInterrupt\n",
      "Process LokyProcess-56:\n",
      "Traceback (most recent call last):\n",
      "  File \"/usr/local/lib/python3.8/dist-packages/joblib/externals/loky/process_executor.py\", line 343, in _sendback_result\n",
      "    result_queue.put(_ResultItem(work_id, result=result,\n",
      "  File \"/usr/local/lib/python3.8/dist-packages/joblib/externals/loky/backend/queues.py\", line 239, in put\n",
      "    with self._wlock:\n",
      "  File \"/usr/local/lib/python3.8/dist-packages/joblib/externals/loky/backend/synchronize.py\", line 104, in __enter__\n",
      "    return self._semlock.acquire()\n",
      "KeyboardInterrupt\n",
      "\n",
      "During handling of the above exception, another exception occurred:\n",
      "\n",
      "Traceback (most recent call last):\n",
      "  File \"/usr/lib/python3.8/multiprocessing/process.py\", line 315, in _bootstrap\n",
      "    self.run()\n",
      "  File \"/usr/lib/python3.8/multiprocessing/process.py\", line 108, in run\n",
      "    self._target(*self._args, **self._kwargs)\n",
      "  File \"/usr/local/lib/python3.8/dist-packages/joblib/externals/loky/process_executor.py\", line 423, in _process_worker\n",
      "    _sendback_result(result_queue, call_item.work_id, result=r)\n",
      "  File \"/usr/local/lib/python3.8/dist-packages/joblib/externals/loky/process_executor.py\", line 347, in _sendback_result\n",
      "    result_queue.put(_ResultItem(work_id, exception=exc))\n",
      "  File \"/usr/local/lib/python3.8/dist-packages/joblib/externals/loky/backend/queues.py\", line 239, in put\n",
      "    with self._wlock:\n",
      "  File \"/usr/local/lib/python3.8/dist-packages/joblib/externals/loky/backend/synchronize.py\", line 104, in __enter__\n",
      "    return self._semlock.acquire()\n",
      "KeyboardInterrupt\n",
      "Process LokyProcess-52:\n",
      "Traceback (most recent call last):\n",
      "  File \"/usr/local/lib/python3.8/dist-packages/joblib/externals/loky/process_executor.py\", line 343, in _sendback_result\n",
      "    result_queue.put(_ResultItem(work_id, result=result,\n",
      "  File \"/usr/local/lib/python3.8/dist-packages/joblib/externals/loky/backend/queues.py\", line 239, in put\n",
      "    with self._wlock:\n",
      "  File \"/usr/local/lib/python3.8/dist-packages/joblib/externals/loky/backend/synchronize.py\", line 104, in __enter__\n",
      "    return self._semlock.acquire()\n",
      "KeyboardInterrupt\n",
      "\n",
      "During handling of the above exception, another exception occurred:\n",
      "\n",
      "Traceback (most recent call last):\n",
      "  File \"/usr/lib/python3.8/multiprocessing/process.py\", line 315, in _bootstrap\n",
      "    self.run()\n",
      "  File \"/usr/lib/python3.8/multiprocessing/process.py\", line 108, in run\n",
      "    self._target(*self._args, **self._kwargs)\n",
      "  File \"/usr/local/lib/python3.8/dist-packages/joblib/externals/loky/process_executor.py\", line 423, in _process_worker\n",
      "    _sendback_result(result_queue, call_item.work_id, result=r)\n",
      "  File \"/usr/local/lib/python3.8/dist-packages/joblib/externals/loky/process_executor.py\", line 347, in _sendback_result\n",
      "    result_queue.put(_ResultItem(work_id, exception=exc))\n",
      "  File \"/usr/local/lib/python3.8/dist-packages/joblib/externals/loky/backend/queues.py\", line 239, in put\n",
      "    with self._wlock:\n",
      "  File \"/usr/local/lib/python3.8/dist-packages/joblib/externals/loky/backend/synchronize.py\", line 104, in __enter__\n",
      "    return self._semlock.acquire()\n",
      "KeyboardInterrupt\n",
      "Process LokyProcess-38:\n",
      "Traceback (most recent call last):\n",
      "  File \"/usr/local/lib/python3.8/dist-packages/joblib/externals/loky/process_executor.py\", line 343, in _sendback_result\n",
      "    result_queue.put(_ResultItem(work_id, result=result,\n",
      "  File \"/usr/local/lib/python3.8/dist-packages/joblib/externals/loky/backend/queues.py\", line 239, in put\n",
      "    with self._wlock:\n",
      "  File \"/usr/local/lib/python3.8/dist-packages/joblib/externals/loky/backend/synchronize.py\", line 104, in __enter__\n",
      "    return self._semlock.acquire()\n",
      "KeyboardInterrupt\n",
      "\n",
      "During handling of the above exception, another exception occurred:\n",
      "\n",
      "Traceback (most recent call last):\n",
      "  File \"/usr/lib/python3.8/multiprocessing/process.py\", line 315, in _bootstrap\n",
      "    self.run()\n",
      "  File \"/usr/lib/python3.8/multiprocessing/process.py\", line 108, in run\n",
      "    self._target(*self._args, **self._kwargs)\n",
      "  File \"/usr/local/lib/python3.8/dist-packages/joblib/externals/loky/process_executor.py\", line 423, in _process_worker\n",
      "    _sendback_result(result_queue, call_item.work_id, result=r)\n",
      "  File \"/usr/local/lib/python3.8/dist-packages/joblib/externals/loky/process_executor.py\", line 347, in _sendback_result\n",
      "    result_queue.put(_ResultItem(work_id, exception=exc))\n",
      "  File \"/usr/local/lib/python3.8/dist-packages/joblib/externals/loky/backend/queues.py\", line 239, in put\n",
      "    with self._wlock:\n",
      "  File \"/usr/local/lib/python3.8/dist-packages/joblib/externals/loky/backend/synchronize.py\", line 104, in __enter__\n",
      "    return self._semlock.acquire()\n",
      "KeyboardInterrupt\n",
      "Process LokyProcess-66:\n",
      "Traceback (most recent call last):\n",
      "  File \"/usr/local/lib/python3.8/dist-packages/joblib/externals/loky/process_executor.py\", line 343, in _sendback_result\n",
      "    result_queue.put(_ResultItem(work_id, result=result,\n",
      "  File \"/usr/local/lib/python3.8/dist-packages/joblib/externals/loky/backend/queues.py\", line 239, in put\n",
      "    with self._wlock:\n",
      "  File \"/usr/local/lib/python3.8/dist-packages/joblib/externals/loky/backend/synchronize.py\", line 104, in __enter__\n",
      "    return self._semlock.acquire()\n",
      "KeyboardInterrupt\n",
      "\n",
      "During handling of the above exception, another exception occurred:\n",
      "\n",
      "Traceback (most recent call last):\n",
      "  File \"/usr/lib/python3.8/multiprocessing/process.py\", line 315, in _bootstrap\n",
      "    self.run()\n",
      "  File \"/usr/lib/python3.8/multiprocessing/process.py\", line 108, in run\n",
      "    self._target(*self._args, **self._kwargs)\n",
      "  File \"/usr/local/lib/python3.8/dist-packages/joblib/externals/loky/process_executor.py\", line 423, in _process_worker\n",
      "    _sendback_result(result_queue, call_item.work_id, result=r)\n",
      "  File \"/usr/local/lib/python3.8/dist-packages/joblib/externals/loky/process_executor.py\", line 347, in _sendback_result\n",
      "    result_queue.put(_ResultItem(work_id, exception=exc))\n",
      "  File \"/usr/local/lib/python3.8/dist-packages/joblib/externals/loky/backend/queues.py\", line 239, in put\n",
      "    with self._wlock:\n",
      "  File \"/usr/local/lib/python3.8/dist-packages/joblib/externals/loky/backend/synchronize.py\", line 104, in __enter__\n",
      "    return self._semlock.acquire()\n",
      "KeyboardInterrupt\n",
      "Process LokyProcess-93:\n",
      "Traceback (most recent call last):\n",
      "  File \"/usr/local/lib/python3.8/dist-packages/joblib/externals/loky/process_executor.py\", line 343, in _sendback_result\n",
      "    result_queue.put(_ResultItem(work_id, result=result,\n",
      "  File \"/usr/local/lib/python3.8/dist-packages/joblib/externals/loky/backend/queues.py\", line 240, in put\n",
      "    self._writer.send_bytes(obj)\n",
      "  File \"/usr/lib/python3.8/multiprocessing/connection.py\", line 200, in send_bytes\n",
      "    self._send_bytes(m[offset:offset + size])\n",
      "  File \"/usr/lib/python3.8/multiprocessing/connection.py\", line 405, in _send_bytes\n",
      "    self._send(buf)\n",
      "  File \"/usr/lib/python3.8/multiprocessing/connection.py\", line 368, in _send\n",
      "    n = write(self._handle, buf)\n",
      "KeyboardInterrupt\n",
      "\n",
      "During handling of the above exception, another exception occurred:\n",
      "\n",
      "Traceback (most recent call last):\n",
      "  File \"/usr/lib/python3.8/multiprocessing/process.py\", line 315, in _bootstrap\n",
      "    self.run()\n",
      "  File \"/usr/lib/python3.8/multiprocessing/process.py\", line 108, in run\n",
      "    self._target(*self._args, **self._kwargs)\n",
      "  File \"/usr/local/lib/python3.8/dist-packages/joblib/externals/loky/process_executor.py\", line 423, in _process_worker\n",
      "    _sendback_result(result_queue, call_item.work_id, result=r)\n",
      "  File \"/usr/local/lib/python3.8/dist-packages/joblib/externals/loky/process_executor.py\", line 347, in _sendback_result\n",
      "    result_queue.put(_ResultItem(work_id, exception=exc))\n",
      "  File \"/usr/local/lib/python3.8/dist-packages/joblib/externals/loky/backend/queues.py\", line 239, in put\n",
      "    with self._wlock:\n",
      "  File \"/usr/local/lib/python3.8/dist-packages/joblib/externals/loky/backend/synchronize.py\", line 104, in __enter__\n",
      "    return self._semlock.acquire()\n",
      "KeyboardInterrupt\n",
      "Process LokyProcess-81:\n",
      "Traceback (most recent call last):\n",
      "  File \"/usr/local/lib/python3.8/dist-packages/joblib/externals/loky/process_executor.py\", line 343, in _sendback_result\n",
      "    result_queue.put(_ResultItem(work_id, result=result,\n",
      "  File \"/usr/local/lib/python3.8/dist-packages/joblib/externals/loky/backend/queues.py\", line 239, in put\n",
      "    with self._wlock:\n",
      "  File \"/usr/local/lib/python3.8/dist-packages/joblib/externals/loky/backend/synchronize.py\", line 104, in __enter__\n",
      "    return self._semlock.acquire()\n",
      "KeyboardInterrupt\n",
      "\n",
      "During handling of the above exception, another exception occurred:\n",
      "\n",
      "Traceback (most recent call last):\n",
      "  File \"/usr/lib/python3.8/multiprocessing/process.py\", line 315, in _bootstrap\n",
      "    self.run()\n",
      "  File \"/usr/lib/python3.8/multiprocessing/process.py\", line 108, in run\n",
      "    self._target(*self._args, **self._kwargs)\n",
      "  File \"/usr/local/lib/python3.8/dist-packages/joblib/externals/loky/process_executor.py\", line 423, in _process_worker\n",
      "    _sendback_result(result_queue, call_item.work_id, result=r)\n",
      "  File \"/usr/local/lib/python3.8/dist-packages/joblib/externals/loky/process_executor.py\", line 347, in _sendback_result\n",
      "    result_queue.put(_ResultItem(work_id, exception=exc))\n",
      "  File \"/usr/local/lib/python3.8/dist-packages/joblib/externals/loky/backend/queues.py\", line 239, in put\n",
      "    with self._wlock:\n",
      "  File \"/usr/local/lib/python3.8/dist-packages/joblib/externals/loky/backend/synchronize.py\", line 104, in __enter__\n",
      "    return self._semlock.acquire()\n",
      "KeyboardInterrupt\n",
      "Process LokyProcess-37:\n",
      "Traceback (most recent call last):\n",
      "  File \"/usr/local/lib/python3.8/dist-packages/joblib/externals/loky/process_executor.py\", line 343, in _sendback_result\n",
      "    result_queue.put(_ResultItem(work_id, result=result,\n",
      "  File \"/usr/local/lib/python3.8/dist-packages/joblib/externals/loky/backend/queues.py\", line 239, in put\n",
      "    with self._wlock:\n",
      "  File \"/usr/local/lib/python3.8/dist-packages/joblib/externals/loky/backend/synchronize.py\", line 104, in __enter__\n",
      "    return self._semlock.acquire()\n",
      "KeyboardInterrupt\n",
      "\n",
      "During handling of the above exception, another exception occurred:\n",
      "\n",
      "Traceback (most recent call last):\n",
      "  File \"/usr/lib/python3.8/multiprocessing/process.py\", line 315, in _bootstrap\n",
      "    self.run()\n",
      "  File \"/usr/lib/python3.8/multiprocessing/process.py\", line 108, in run\n",
      "    self._target(*self._args, **self._kwargs)\n",
      "  File \"/usr/local/lib/python3.8/dist-packages/joblib/externals/loky/process_executor.py\", line 423, in _process_worker\n",
      "    _sendback_result(result_queue, call_item.work_id, result=r)\n",
      "  File \"/usr/local/lib/python3.8/dist-packages/joblib/externals/loky/process_executor.py\", line 347, in _sendback_result\n",
      "    result_queue.put(_ResultItem(work_id, exception=exc))\n",
      "  File \"/usr/local/lib/python3.8/dist-packages/joblib/externals/loky/backend/queues.py\", line 239, in put\n",
      "    with self._wlock:\n",
      "  File \"/usr/local/lib/python3.8/dist-packages/joblib/externals/loky/backend/synchronize.py\", line 104, in __enter__\n",
      "    return self._semlock.acquire()\n",
      "KeyboardInterrupt\n",
      "Process LokyProcess-2:\n",
      "Traceback (most recent call last):\n",
      "  File \"/usr/local/lib/python3.8/dist-packages/joblib/externals/loky/process_executor.py\", line 343, in _sendback_result\n",
      "    result_queue.put(_ResultItem(work_id, result=result,\n",
      "  File \"/usr/local/lib/python3.8/dist-packages/joblib/externals/loky/backend/queues.py\", line 239, in put\n",
      "    with self._wlock:\n",
      "  File \"/usr/local/lib/python3.8/dist-packages/joblib/externals/loky/backend/synchronize.py\", line 104, in __enter__\n",
      "    return self._semlock.acquire()\n",
      "KeyboardInterrupt\n",
      "\n",
      "During handling of the above exception, another exception occurred:\n",
      "\n",
      "Traceback (most recent call last):\n",
      "  File \"/usr/lib/python3.8/multiprocessing/process.py\", line 315, in _bootstrap\n",
      "    self.run()\n",
      "  File \"/usr/lib/python3.8/multiprocessing/process.py\", line 108, in run\n",
      "    self._target(*self._args, **self._kwargs)\n",
      "  File \"/usr/local/lib/python3.8/dist-packages/joblib/externals/loky/process_executor.py\", line 423, in _process_worker\n",
      "    _sendback_result(result_queue, call_item.work_id, result=r)\n",
      "  File \"/usr/local/lib/python3.8/dist-packages/joblib/externals/loky/process_executor.py\", line 347, in _sendback_result\n",
      "    result_queue.put(_ResultItem(work_id, exception=exc))\n",
      "  File \"/usr/local/lib/python3.8/dist-packages/joblib/externals/loky/backend/queues.py\", line 239, in put\n",
      "    with self._wlock:\n",
      "  File \"/usr/local/lib/python3.8/dist-packages/joblib/externals/loky/backend/synchronize.py\", line 104, in __enter__\n",
      "    return self._semlock.acquire()\n",
      "KeyboardInterrupt\n",
      "Process LokyProcess-55:\n",
      "Traceback (most recent call last):\n",
      "  File \"/usr/local/lib/python3.8/dist-packages/joblib/externals/loky/process_executor.py\", line 343, in _sendback_result\n",
      "    result_queue.put(_ResultItem(work_id, result=result,\n",
      "  File \"/usr/local/lib/python3.8/dist-packages/joblib/externals/loky/backend/queues.py\", line 239, in put\n",
      "    with self._wlock:\n",
      "  File \"/usr/local/lib/python3.8/dist-packages/joblib/externals/loky/backend/synchronize.py\", line 104, in __enter__\n",
      "    return self._semlock.acquire()\n",
      "KeyboardInterrupt\n",
      "\n",
      "During handling of the above exception, another exception occurred:\n",
      "\n",
      "Traceback (most recent call last):\n",
      "  File \"/usr/lib/python3.8/multiprocessing/process.py\", line 315, in _bootstrap\n",
      "    self.run()\n",
      "  File \"/usr/lib/python3.8/multiprocessing/process.py\", line 108, in run\n",
      "    self._target(*self._args, **self._kwargs)\n",
      "  File \"/usr/local/lib/python3.8/dist-packages/joblib/externals/loky/process_executor.py\", line 423, in _process_worker\n",
      "    _sendback_result(result_queue, call_item.work_id, result=r)\n",
      "  File \"/usr/local/lib/python3.8/dist-packages/joblib/externals/loky/process_executor.py\", line 347, in _sendback_result\n",
      "    result_queue.put(_ResultItem(work_id, exception=exc))\n",
      "  File \"/usr/local/lib/python3.8/dist-packages/joblib/externals/loky/backend/queues.py\", line 239, in put\n",
      "    with self._wlock:\n",
      "  File \"/usr/local/lib/python3.8/dist-packages/joblib/externals/loky/backend/synchronize.py\", line 104, in __enter__\n",
      "    return self._semlock.acquire()\n",
      "KeyboardInterrupt\n",
      "Process LokyProcess-30:\n",
      "Traceback (most recent call last):\n",
      "  File \"/usr/local/lib/python3.8/dist-packages/joblib/externals/loky/process_executor.py\", line 343, in _sendback_result\n",
      "    result_queue.put(_ResultItem(work_id, result=result,\n",
      "  File \"/usr/local/lib/python3.8/dist-packages/joblib/externals/loky/backend/queues.py\", line 240, in put\n",
      "    self._writer.send_bytes(obj)\n",
      "  File \"/usr/lib/python3.8/multiprocessing/connection.py\", line 200, in send_bytes\n",
      "    self._send_bytes(m[offset:offset + size])\n",
      "  File \"/usr/lib/python3.8/multiprocessing/connection.py\", line 404, in _send_bytes\n",
      "    self._send(header)\n",
      "  File \"/usr/lib/python3.8/multiprocessing/connection.py\", line 368, in _send\n",
      "    n = write(self._handle, buf)\n",
      "KeyboardInterrupt\n",
      "\n",
      "During handling of the above exception, another exception occurred:\n",
      "\n",
      "Traceback (most recent call last):\n",
      "  File \"/usr/lib/python3.8/multiprocessing/process.py\", line 315, in _bootstrap\n",
      "    self.run()\n",
      "  File \"/usr/lib/python3.8/multiprocessing/process.py\", line 108, in run\n",
      "    self._target(*self._args, **self._kwargs)\n",
      "  File \"/usr/local/lib/python3.8/dist-packages/joblib/externals/loky/process_executor.py\", line 423, in _process_worker\n",
      "    _sendback_result(result_queue, call_item.work_id, result=r)\n",
      "  File \"/usr/local/lib/python3.8/dist-packages/joblib/externals/loky/process_executor.py\", line 347, in _sendback_result\n",
      "    result_queue.put(_ResultItem(work_id, exception=exc))\n",
      "  File \"/usr/local/lib/python3.8/dist-packages/joblib/externals/loky/backend/queues.py\", line 239, in put\n",
      "    with self._wlock:\n",
      "  File \"/usr/local/lib/python3.8/dist-packages/joblib/externals/loky/backend/synchronize.py\", line 104, in __enter__\n",
      "    return self._semlock.acquire()\n",
      "KeyboardInterrupt\n",
      "Process LokyProcess-64:\n",
      "Traceback (most recent call last):\n",
      "  File \"/usr/local/lib/python3.8/dist-packages/joblib/externals/loky/process_executor.py\", line 343, in _sendback_result\n",
      "    result_queue.put(_ResultItem(work_id, result=result,\n",
      "  File \"/usr/local/lib/python3.8/dist-packages/joblib/externals/loky/backend/queues.py\", line 239, in put\n",
      "    with self._wlock:\n",
      "  File \"/usr/local/lib/python3.8/dist-packages/joblib/externals/loky/backend/synchronize.py\", line 104, in __enter__\n",
      "    return self._semlock.acquire()\n",
      "KeyboardInterrupt\n",
      "\n",
      "During handling of the above exception, another exception occurred:\n",
      "\n",
      "Traceback (most recent call last):\n",
      "  File \"/usr/lib/python3.8/multiprocessing/process.py\", line 315, in _bootstrap\n",
      "    self.run()\n",
      "  File \"/usr/lib/python3.8/multiprocessing/process.py\", line 108, in run\n",
      "    self._target(*self._args, **self._kwargs)\n",
      "  File \"/usr/local/lib/python3.8/dist-packages/joblib/externals/loky/process_executor.py\", line 423, in _process_worker\n",
      "    _sendback_result(result_queue, call_item.work_id, result=r)\n",
      "  File \"/usr/local/lib/python3.8/dist-packages/joblib/externals/loky/process_executor.py\", line 347, in _sendback_result\n",
      "    result_queue.put(_ResultItem(work_id, exception=exc))\n",
      "  File \"/usr/local/lib/python3.8/dist-packages/joblib/externals/loky/backend/queues.py\", line 239, in put\n",
      "    with self._wlock:\n",
      "  File \"/usr/local/lib/python3.8/dist-packages/joblib/externals/loky/backend/synchronize.py\", line 104, in __enter__\n",
      "    return self._semlock.acquire()\n",
      "KeyboardInterrupt\n",
      "Process LokyProcess-14:\n",
      "Traceback (most recent call last):\n",
      "  File \"/usr/local/lib/python3.8/dist-packages/joblib/externals/loky/process_executor.py\", line 343, in _sendback_result\n",
      "    result_queue.put(_ResultItem(work_id, result=result,\n",
      "  File \"/usr/local/lib/python3.8/dist-packages/joblib/externals/loky/backend/queues.py\", line 239, in put\n",
      "    with self._wlock:\n",
      "  File \"/usr/local/lib/python3.8/dist-packages/joblib/externals/loky/backend/synchronize.py\", line 104, in __enter__\n",
      "    return self._semlock.acquire()\n",
      "KeyboardInterrupt\n",
      "\n",
      "During handling of the above exception, another exception occurred:\n",
      "\n",
      "Traceback (most recent call last):\n",
      "  File \"/usr/lib/python3.8/multiprocessing/process.py\", line 315, in _bootstrap\n",
      "    self.run()\n",
      "  File \"/usr/lib/python3.8/multiprocessing/process.py\", line 108, in run\n",
      "    self._target(*self._args, **self._kwargs)\n",
      "  File \"/usr/local/lib/python3.8/dist-packages/joblib/externals/loky/process_executor.py\", line 423, in _process_worker\n",
      "    _sendback_result(result_queue, call_item.work_id, result=r)\n",
      "  File \"/usr/local/lib/python3.8/dist-packages/joblib/externals/loky/process_executor.py\", line 347, in _sendback_result\n",
      "    result_queue.put(_ResultItem(work_id, exception=exc))\n",
      "  File \"/usr/local/lib/python3.8/dist-packages/joblib/externals/loky/backend/queues.py\", line 239, in put\n",
      "    with self._wlock:\n",
      "  File \"/usr/local/lib/python3.8/dist-packages/joblib/externals/loky/backend/synchronize.py\", line 104, in __enter__\n",
      "    return self._semlock.acquire()\n",
      "KeyboardInterrupt\n",
      "Process LokyProcess-51:\n",
      "Traceback (most recent call last):\n",
      "  File \"/usr/local/lib/python3.8/dist-packages/joblib/externals/loky/process_executor.py\", line 343, in _sendback_result\n",
      "    result_queue.put(_ResultItem(work_id, result=result,\n",
      "  File \"/usr/local/lib/python3.8/dist-packages/joblib/externals/loky/backend/queues.py\", line 239, in put\n",
      "    with self._wlock:\n",
      "  File \"/usr/local/lib/python3.8/dist-packages/joblib/externals/loky/backend/synchronize.py\", line 104, in __enter__\n",
      "    return self._semlock.acquire()\n",
      "KeyboardInterrupt\n",
      "\n",
      "During handling of the above exception, another exception occurred:\n",
      "\n",
      "Traceback (most recent call last):\n",
      "  File \"/usr/lib/python3.8/multiprocessing/process.py\", line 315, in _bootstrap\n",
      "    self.run()\n",
      "  File \"/usr/lib/python3.8/multiprocessing/process.py\", line 108, in run\n",
      "    self._target(*self._args, **self._kwargs)\n",
      "  File \"/usr/local/lib/python3.8/dist-packages/joblib/externals/loky/process_executor.py\", line 423, in _process_worker\n",
      "    _sendback_result(result_queue, call_item.work_id, result=r)\n",
      "  File \"/usr/local/lib/python3.8/dist-packages/joblib/externals/loky/process_executor.py\", line 347, in _sendback_result\n",
      "    result_queue.put(_ResultItem(work_id, exception=exc))\n",
      "  File \"/usr/local/lib/python3.8/dist-packages/joblib/externals/loky/backend/queues.py\", line 239, in put\n",
      "    with self._wlock:\n",
      "  File \"/usr/local/lib/python3.8/dist-packages/joblib/externals/loky/backend/synchronize.py\", line 104, in __enter__\n",
      "    return self._semlock.acquire()\n",
      "KeyboardInterrupt\n",
      "Process LokyProcess-58:\n",
      "Traceback (most recent call last):\n",
      "  File \"/usr/local/lib/python3.8/dist-packages/joblib/externals/loky/process_executor.py\", line 343, in _sendback_result\n",
      "    result_queue.put(_ResultItem(work_id, result=result,\n",
      "  File \"/usr/local/lib/python3.8/dist-packages/joblib/externals/loky/backend/queues.py\", line 239, in put\n",
      "    with self._wlock:\n",
      "  File \"/usr/local/lib/python3.8/dist-packages/joblib/externals/loky/backend/synchronize.py\", line 104, in __enter__\n",
      "    return self._semlock.acquire()\n",
      "KeyboardInterrupt\n",
      "\n",
      "During handling of the above exception, another exception occurred:\n",
      "\n",
      "Traceback (most recent call last):\n",
      "  File \"/usr/lib/python3.8/multiprocessing/process.py\", line 315, in _bootstrap\n",
      "    self.run()\n",
      "  File \"/usr/lib/python3.8/multiprocessing/process.py\", line 108, in run\n",
      "    self._target(*self._args, **self._kwargs)\n",
      "  File \"/usr/local/lib/python3.8/dist-packages/joblib/externals/loky/process_executor.py\", line 423, in _process_worker\n",
      "    _sendback_result(result_queue, call_item.work_id, result=r)\n",
      "  File \"/usr/local/lib/python3.8/dist-packages/joblib/externals/loky/process_executor.py\", line 347, in _sendback_result\n",
      "    result_queue.put(_ResultItem(work_id, exception=exc))\n",
      "  File \"/usr/local/lib/python3.8/dist-packages/joblib/externals/loky/backend/queues.py\", line 239, in put\n",
      "    with self._wlock:\n",
      "  File \"/usr/local/lib/python3.8/dist-packages/joblib/externals/loky/backend/synchronize.py\", line 104, in __enter__\n",
      "    return self._semlock.acquire()\n",
      "KeyboardInterrupt\n",
      "Process LokyProcess-76:\n",
      "Traceback (most recent call last):\n",
      "  File \"/usr/local/lib/python3.8/dist-packages/joblib/externals/loky/process_executor.py\", line 343, in _sendback_result\n",
      "    result_queue.put(_ResultItem(work_id, result=result,\n",
      "  File \"/usr/local/lib/python3.8/dist-packages/joblib/externals/loky/backend/queues.py\", line 239, in put\n",
      "    with self._wlock:\n",
      "  File \"/usr/local/lib/python3.8/dist-packages/joblib/externals/loky/backend/synchronize.py\", line 104, in __enter__\n",
      "    return self._semlock.acquire()\n",
      "KeyboardInterrupt\n",
      "\n",
      "During handling of the above exception, another exception occurred:\n",
      "\n",
      "Traceback (most recent call last):\n",
      "  File \"/usr/lib/python3.8/multiprocessing/process.py\", line 315, in _bootstrap\n",
      "    self.run()\n",
      "  File \"/usr/lib/python3.8/multiprocessing/process.py\", line 108, in run\n",
      "    self._target(*self._args, **self._kwargs)\n",
      "  File \"/usr/local/lib/python3.8/dist-packages/joblib/externals/loky/process_executor.py\", line 423, in _process_worker\n",
      "    _sendback_result(result_queue, call_item.work_id, result=r)\n",
      "  File \"/usr/local/lib/python3.8/dist-packages/joblib/externals/loky/process_executor.py\", line 347, in _sendback_result\n",
      "    result_queue.put(_ResultItem(work_id, exception=exc))\n",
      "  File \"/usr/local/lib/python3.8/dist-packages/joblib/externals/loky/backend/queues.py\", line 239, in put\n",
      "    with self._wlock:\n",
      "  File \"/usr/local/lib/python3.8/dist-packages/joblib/externals/loky/backend/synchronize.py\", line 104, in __enter__\n",
      "    return self._semlock.acquire()\n",
      "KeyboardInterrupt\n",
      "Process LokyProcess-61:\n",
      "Traceback (most recent call last):\n",
      "  File \"/usr/local/lib/python3.8/dist-packages/joblib/externals/loky/process_executor.py\", line 343, in _sendback_result\n",
      "    result_queue.put(_ResultItem(work_id, result=result,\n",
      "  File \"/usr/local/lib/python3.8/dist-packages/joblib/externals/loky/backend/queues.py\", line 239, in put\n",
      "    with self._wlock:\n",
      "  File \"/usr/local/lib/python3.8/dist-packages/joblib/externals/loky/backend/synchronize.py\", line 104, in __enter__\n",
      "    return self._semlock.acquire()\n",
      "KeyboardInterrupt\n",
      "\n",
      "During handling of the above exception, another exception occurred:\n",
      "\n",
      "Traceback (most recent call last):\n",
      "  File \"/usr/lib/python3.8/multiprocessing/process.py\", line 315, in _bootstrap\n",
      "    self.run()\n",
      "  File \"/usr/lib/python3.8/multiprocessing/process.py\", line 108, in run\n",
      "    self._target(*self._args, **self._kwargs)\n",
      "  File \"/usr/local/lib/python3.8/dist-packages/joblib/externals/loky/process_executor.py\", line 423, in _process_worker\n",
      "    _sendback_result(result_queue, call_item.work_id, result=r)\n",
      "  File \"/usr/local/lib/python3.8/dist-packages/joblib/externals/loky/process_executor.py\", line 347, in _sendback_result\n",
      "    result_queue.put(_ResultItem(work_id, exception=exc))\n",
      "  File \"/usr/local/lib/python3.8/dist-packages/joblib/externals/loky/backend/queues.py\", line 239, in put\n",
      "    with self._wlock:\n",
      "  File \"/usr/local/lib/python3.8/dist-packages/joblib/externals/loky/backend/synchronize.py\", line 104, in __enter__\n",
      "    return self._semlock.acquire()\n",
      "KeyboardInterrupt\n",
      "Process LokyProcess-50:\n",
      "Traceback (most recent call last):\n",
      "  File \"/usr/local/lib/python3.8/dist-packages/joblib/externals/loky/process_executor.py\", line 343, in _sendback_result\n",
      "    result_queue.put(_ResultItem(work_id, result=result,\n",
      "  File \"/usr/local/lib/python3.8/dist-packages/joblib/externals/loky/backend/queues.py\", line 239, in put\n",
      "    with self._wlock:\n",
      "  File \"/usr/local/lib/python3.8/dist-packages/joblib/externals/loky/backend/synchronize.py\", line 104, in __enter__\n",
      "    return self._semlock.acquire()\n",
      "KeyboardInterrupt\n",
      "\n",
      "During handling of the above exception, another exception occurred:\n",
      "\n",
      "Traceback (most recent call last):\n",
      "  File \"/usr/lib/python3.8/multiprocessing/process.py\", line 315, in _bootstrap\n",
      "    self.run()\n",
      "  File \"/usr/lib/python3.8/multiprocessing/process.py\", line 108, in run\n",
      "    self._target(*self._args, **self._kwargs)\n",
      "  File \"/usr/local/lib/python3.8/dist-packages/joblib/externals/loky/process_executor.py\", line 423, in _process_worker\n",
      "    _sendback_result(result_queue, call_item.work_id, result=r)\n",
      "  File \"/usr/local/lib/python3.8/dist-packages/joblib/externals/loky/process_executor.py\", line 347, in _sendback_result\n",
      "    result_queue.put(_ResultItem(work_id, exception=exc))\n",
      "  File \"/usr/local/lib/python3.8/dist-packages/joblib/externals/loky/backend/queues.py\", line 239, in put\n",
      "    with self._wlock:\n",
      "  File \"/usr/local/lib/python3.8/dist-packages/joblib/externals/loky/backend/synchronize.py\", line 104, in __enter__\n",
      "    return self._semlock.acquire()\n",
      "KeyboardInterrupt\n",
      "Process LokyProcess-79:\n",
      "Traceback (most recent call last):\n",
      "  File \"/usr/local/lib/python3.8/dist-packages/joblib/externals/loky/process_executor.py\", line 343, in _sendback_result\n",
      "    result_queue.put(_ResultItem(work_id, result=result,\n",
      "  File \"/usr/local/lib/python3.8/dist-packages/joblib/externals/loky/backend/queues.py\", line 239, in put\n",
      "    with self._wlock:\n",
      "  File \"/usr/local/lib/python3.8/dist-packages/joblib/externals/loky/backend/synchronize.py\", line 104, in __enter__\n",
      "    return self._semlock.acquire()\n",
      "KeyboardInterrupt\n",
      "\n",
      "During handling of the above exception, another exception occurred:\n",
      "\n",
      "Traceback (most recent call last):\n",
      "  File \"/usr/lib/python3.8/multiprocessing/process.py\", line 315, in _bootstrap\n",
      "    self.run()\n",
      "  File \"/usr/lib/python3.8/multiprocessing/process.py\", line 108, in run\n",
      "    self._target(*self._args, **self._kwargs)\n",
      "  File \"/usr/local/lib/python3.8/dist-packages/joblib/externals/loky/process_executor.py\", line 423, in _process_worker\n",
      "    _sendback_result(result_queue, call_item.work_id, result=r)\n",
      "  File \"/usr/local/lib/python3.8/dist-packages/joblib/externals/loky/process_executor.py\", line 347, in _sendback_result\n",
      "    result_queue.put(_ResultItem(work_id, exception=exc))\n",
      "  File \"/usr/local/lib/python3.8/dist-packages/joblib/externals/loky/backend/queues.py\", line 239, in put\n",
      "    with self._wlock:\n",
      "  File \"/usr/local/lib/python3.8/dist-packages/joblib/externals/loky/backend/synchronize.py\", line 104, in __enter__\n",
      "    return self._semlock.acquire()\n",
      "KeyboardInterrupt\n",
      "Process LokyProcess-75:\n",
      "Traceback (most recent call last):\n",
      "  File \"/usr/local/lib/python3.8/dist-packages/joblib/externals/loky/process_executor.py\", line 343, in _sendback_result\n",
      "    result_queue.put(_ResultItem(work_id, result=result,\n",
      "  File \"/usr/local/lib/python3.8/dist-packages/joblib/externals/loky/backend/queues.py\", line 239, in put\n",
      "    with self._wlock:\n",
      "  File \"/usr/local/lib/python3.8/dist-packages/joblib/externals/loky/backend/synchronize.py\", line 104, in __enter__\n",
      "    return self._semlock.acquire()\n",
      "KeyboardInterrupt\n",
      "\n",
      "During handling of the above exception, another exception occurred:\n",
      "\n",
      "Traceback (most recent call last):\n",
      "  File \"/usr/lib/python3.8/multiprocessing/process.py\", line 315, in _bootstrap\n",
      "    self.run()\n",
      "  File \"/usr/lib/python3.8/multiprocessing/process.py\", line 108, in run\n",
      "    self._target(*self._args, **self._kwargs)\n",
      "  File \"/usr/local/lib/python3.8/dist-packages/joblib/externals/loky/process_executor.py\", line 423, in _process_worker\n",
      "    _sendback_result(result_queue, call_item.work_id, result=r)\n",
      "  File \"/usr/local/lib/python3.8/dist-packages/joblib/externals/loky/process_executor.py\", line 347, in _sendback_result\n",
      "    result_queue.put(_ResultItem(work_id, exception=exc))\n",
      "  File \"/usr/local/lib/python3.8/dist-packages/joblib/externals/loky/backend/queues.py\", line 239, in put\n",
      "    with self._wlock:\n",
      "  File \"/usr/local/lib/python3.8/dist-packages/joblib/externals/loky/backend/synchronize.py\", line 104, in __enter__\n",
      "    return self._semlock.acquire()\n",
      "KeyboardInterrupt\n",
      "Process LokyProcess-32:\n",
      "Traceback (most recent call last):\n",
      "  File \"/usr/local/lib/python3.8/dist-packages/joblib/externals/loky/process_executor.py\", line 343, in _sendback_result\n",
      "    result_queue.put(_ResultItem(work_id, result=result,\n",
      "  File \"/usr/local/lib/python3.8/dist-packages/joblib/externals/loky/backend/queues.py\", line 239, in put\n",
      "    with self._wlock:\n",
      "  File \"/usr/local/lib/python3.8/dist-packages/joblib/externals/loky/backend/synchronize.py\", line 104, in __enter__\n",
      "    return self._semlock.acquire()\n",
      "KeyboardInterrupt\n",
      "\n",
      "During handling of the above exception, another exception occurred:\n",
      "\n",
      "Traceback (most recent call last):\n",
      "  File \"/usr/lib/python3.8/multiprocessing/process.py\", line 315, in _bootstrap\n",
      "    self.run()\n",
      "  File \"/usr/lib/python3.8/multiprocessing/process.py\", line 108, in run\n",
      "    self._target(*self._args, **self._kwargs)\n",
      "  File \"/usr/local/lib/python3.8/dist-packages/joblib/externals/loky/process_executor.py\", line 423, in _process_worker\n",
      "    _sendback_result(result_queue, call_item.work_id, result=r)\n",
      "  File \"/usr/local/lib/python3.8/dist-packages/joblib/externals/loky/process_executor.py\", line 347, in _sendback_result\n",
      "    result_queue.put(_ResultItem(work_id, exception=exc))\n",
      "  File \"/usr/local/lib/python3.8/dist-packages/joblib/externals/loky/backend/queues.py\", line 239, in put\n",
      "    with self._wlock:\n",
      "  File \"/usr/local/lib/python3.8/dist-packages/joblib/externals/loky/backend/synchronize.py\", line 104, in __enter__\n",
      "    return self._semlock.acquire()\n",
      "KeyboardInterrupt\n",
      "Process LokyProcess-36:\n",
      "Traceback (most recent call last):\n",
      "  File \"/usr/local/lib/python3.8/dist-packages/joblib/externals/loky/process_executor.py\", line 343, in _sendback_result\n",
      "    result_queue.put(_ResultItem(work_id, result=result,\n",
      "  File \"/usr/local/lib/python3.8/dist-packages/joblib/externals/loky/backend/queues.py\", line 239, in put\n",
      "    with self._wlock:\n",
      "  File \"/usr/local/lib/python3.8/dist-packages/joblib/externals/loky/backend/synchronize.py\", line 104, in __enter__\n",
      "    return self._semlock.acquire()\n",
      "KeyboardInterrupt\n",
      "\n",
      "During handling of the above exception, another exception occurred:\n",
      "\n",
      "Traceback (most recent call last):\n",
      "  File \"/usr/lib/python3.8/multiprocessing/process.py\", line 315, in _bootstrap\n",
      "    self.run()\n",
      "  File \"/usr/lib/python3.8/multiprocessing/process.py\", line 108, in run\n",
      "    self._target(*self._args, **self._kwargs)\n",
      "  File \"/usr/local/lib/python3.8/dist-packages/joblib/externals/loky/process_executor.py\", line 423, in _process_worker\n",
      "    _sendback_result(result_queue, call_item.work_id, result=r)\n",
      "  File \"/usr/local/lib/python3.8/dist-packages/joblib/externals/loky/process_executor.py\", line 347, in _sendback_result\n",
      "    result_queue.put(_ResultItem(work_id, exception=exc))\n",
      "  File \"/usr/local/lib/python3.8/dist-packages/joblib/externals/loky/backend/queues.py\", line 239, in put\n",
      "    with self._wlock:\n",
      "  File \"/usr/local/lib/python3.8/dist-packages/joblib/externals/loky/backend/synchronize.py\", line 104, in __enter__\n",
      "    return self._semlock.acquire()\n",
      "KeyboardInterrupt\n",
      "\n",
      "KeyboardInterrupt\n",
      "\n"
     ]
    }
   ],
   "source": [
    "\n",
    "videos = Parallel(n_jobs=-5)(delayed(load_video)(path) for path in tqdm(video_paths))\n",
    "videos = tf.ragged.stack(videos)"
   ]
  },
  {
   "cell_type": "code",
   "execution_count": null,
   "id": "38d06b4c-20ae-4038-9c1c-b107fb62c25a",
   "metadata": {},
   "outputs": [],
   "source": []
  }
 ],
 "metadata": {
  "kernelspec": {
   "display_name": "Python 3 (ipykernel)",
   "language": "python",
   "name": "python3"
  },
  "language_info": {
   "codemirror_mode": {
    "name": "ipython",
    "version": 3
   },
   "file_extension": ".py",
   "mimetype": "text/x-python",
   "name": "python",
   "nbconvert_exporter": "python",
   "pygments_lexer": "ipython3",
   "version": "3.8.10"
  }
 },
 "nbformat": 4,
 "nbformat_minor": 5
}
